Workbook
Name CC: 'RESULTADO FINAL'!$AL$1
Name CCM: 'RESULTADO FINAL'!$V$1
Name CDISP: 'RESULTADO FINAL'!$X$1
Name CINT: 'RESULTADO FINAL'!$Y$1
Name CND: 'RESULTADO FINAL'!$W$1
Name FDP: 'RESULTADO FINAL'!$Z$1
Name HD: 'RESULTADO FINAL'!$AA$1
Name HEF: 'RESULTADO FINAL'!$AB$1
Name HER: 'RESULTADO FINAL'!$AC$1
Name HL: 'RESULTADO FINAL'!$AD$1
Name HVC: 'RESULTADO FINAL'!$AE$1
Name HVL: 'RESULTADO FINAL'!$AF$1
Name LAA: 'RESULTADO FINAL'!$AH$1
Name LND: 'RESULTADO FINAL'!$AI$1
Name LOC: 'RESULTADO FINAL'!$AG$1
Name MMI: 'RESULTADO FINAL'!$AJ$1
Name MND: 'RESULTADO FINAL'!$AK$1
Name NOAV: 'RESULTADO FINAL'!$AM$1
Name NOL: 'RESULTADO FINAL'!$AN$1
Name NOPM: 'RESULTADO FINAL'!$AO$1

Sheet Folha1
A1: description | B1: name | C1: value | D1: name2 | E1: description3 | F1: name4 | G1: value5 | H1: name6 | I1: description7 | J1: name8 | K1: value9 | L1: name10 | M1: description11 | N1: name12 | O1: value13 | P1: name14 | Q1: description15 | R1: name16 | S1: value17 | T1: name18 | U1: description19 | V1: name20 | W1: value21
A2: Attribute Hiding Factor | B2: AHF | C2: 0
A3: Attribute Inheritance Factor | B3: AIF | C3: 0,0984
A4: Coupling Factor | B4: CF | C4: 0,9006
A5: Effectiveness | B5: Effectiveness | C5: 1,4187
A6: Extendibility | B6: Extendibility | C6: 1,9714
A7: Flexibility | B7: Flexibility | C7: 3,2968
A8: Functionality | B8: Functionality | C8: 1,6606
A9: Halstead Difficulty | B9: PRHD | C9: 677,2155
A10: Halstead Effort | B10: PRCHEF | C10: 1671949,5538
A11: Halstead Errors | B11: PRCHER | C11: 8,8631
A12: Halstead Length | B12: PRCHL | C12: 2892
A13: Halstead Vocabulary | B13: PRCHVC | C13: 811
... A30: Understandability | B30: Understandability | C30: -1,7088
D31: battleship | E31: Abstractness | F31: A | G31: 0,3333
D32: battleship | E32: Afferent Coupling | F32: Ca | G32: 0
D33: battleship | E33: Efferent Coupling | F33: Ce | G33: 7
D34: battleship | E34: Halstead Difficulty | F34: PAHD | G34: 677,2155
D35: battleship | E35: Halstead Effort | F35: PACHEF | G35: 1671949,5538
D36: battleship | E36: Halstead Errors | F36: PACHER | G36: 8,8631
D37: battleship | E37: Halstead Length | F37: PACHL | G37: 2892
D38: battleship | E38: Halstead Vocabulary | F38: PACHVC | G38: 811
D39: battleship | E39: Halstead Volume | F39: PAHVL | G39: 18947,6665
D40: battleship | E40: Instability | F40: I | G40: 1,0
D41: battleship | E41: Lines Of Code | F41: PLOC | G41: 1668
D42: battleship | E42: Maintainability Index | F42: PAMI | G42: 0,0
... D52: battleship | E52: Number Of Static Classes | F52: PNOSC | G52: 0
D53: battleship | H53: Barge | I53: Access To Foreign Data | J53: ATFD | K53: 1
D54: battleship | H54: Barge | I54: Cognitive Complexity | J54: CCC | K54: 0
D55: battleship | H55: Barge | I55: Coupling Between Objects | J55: CBO | K55: 5
D56: battleship | H56: Barge | I56: Data Abstraction Coupling | J56: DAC | K56: 0
D57: battleship | H57: Barge | I57: Depth Of Inheritance Tree | J57: DIT | K57: 2
D58: battleship | H58: Barge | I58: Halstead Difficulty | J58: CHD | K58: 7,5
D59: battleship | H59: Barge | I59: Halstead Effort | J59: CHEF | K59: 485,4378
D60: battleship | H60: Barge | I60: Halstead Errors | J60: CHER | K60: 0,0206
D61: battleship | H61: Barge | I61: Halstead Length | J61: CHL | K61: 17
D62: battleship | H62: Barge | I62: Halstead Vocabulary | J62: CHVC | K62: 14
D63: battleship | H63: Barge | I63: Halstead Volume | J63: CHVL | K63: 64,725
D64: battleship | H64: Barge | I64: Lack Of Cohesion Of Methods | J64: LCOM | K64: 0
... D81: battleship | H81: Barge | I81: Weighted Methods Per Class | J81: WMC | K81: 1
...

Sheet System
A1: description | B1: name | C1: value
A2: Attribute Hiding Factor | B2: AHF | C2: 0
A3: Attribute Inheritance Factor | B3: AIF | C3: 0,0984
A4: Coupling Factor | B4: CF | C4: 0,9006
A5: Effectiveness | B5: Effectiveness | C5: 1,4187
A6: Extendibility | B6: Extendibility | C6: 1,9714
A7: Flexibility | B7: Flexibility | C7: 3,2968
A8: Functionality | B8: Functionality | C8: 1,6606
A9: Halstead Difficulty | B9: PRHD | C9: 677,2155
A10: Halstead Effort | B10: PRCHEF | C10: 1671949,5538
A11: Halstead Errors | B11: PRCHER | C11: 8,8631
A12: Halstead Length | B12: PRCHL | C12: 2892
... A30: Understandability | B30: Understandability | C30: -1,7088

Sheet Package
A1: name2 | B1: description3 | C1: name4 | D1: value5
A2: battleship | B2: Abstractness | C2: A | D2: 0,3333
A3: battleship | B3: Afferent Coupling | C3: Ca | D3: 0
A4: battleship | B4: Efferent Coupling | C4: Ce | D4: 7
A5: battleship | B5: Halstead Difficulty | C5: PAHD | D5: 677,2155
A6: battleship | B6: Halstead Effort | C6: PACHEF | D6: 1671949,5538
A7: battleship | B7: Halstead Errors | C7: PACHER | D7: 8,8631
A8: battleship | B8: Halstead Length | C8: PACHL | D8: 2892
A9: battleship | B9: Halstead Vocabulary | C9: PACHVC | D9: 811
A10: battleship | B10: Halstead Volume | C10: PAHVL | D10: 18947,6665
A11: battleship | B11: Instability | C11: I | D11: 1,0
A12: battleship | B12: Lines Of Code | C12: PLOC | D12: 1668
... A23: battleship | B23: Number Of Static Classes | C23: PNOSC | D23: 0
A24: battleship
A25: battleship
A26: battleship
A27: battleship
A28: battleship
A29: battleship
A30: battleship
A31: battleship
A32: battleship
A33: battleship
A34: battleship
A35: battleship
... A3814: battleship

Sheet Class
A1: name6 | B1: description7 | C1: name8 | D1: value9
A2: Barge | B2: Access To Foreign Data | C2: ATFD | D2: 1
A3: Barge | B3: Cognitive Complexity | C3: CCC | D3: 0
A4: Barge | B4: Coupling Between Objects | C4: CBO | D4: 5
A5: Barge | B5: Data Abstraction Coupling | C5: DAC | D5: 0
A6: Barge | B6: Depth Of Inheritance Tree | C6: DIT | D6: 2
A7: Barge | B7: Halstead Difficulty | C7: CHD | D7: 7,5
A8: Barge | B8: Halstead Effort | C8: CHEF | D8: 485,4378
A9: Barge | B9: Halstead Errors | C9: CHER | D9: 0,0206
A10: Barge | B10: Halstead Length | C10: CHL | D10: 17
A11: Barge | B11: Halstead Vocabulary | C11: CHVC | D11: 14
A12: Barge | B12: Halstead Volume | C12: CHVL | D12: 64,725
... A30: Barge | B30: Weighted Methods Per Class | C30: WMC | D30: 1
A31: Barge
A32: Barge
A33: Barge
A34: Barge
A35: Barge
A36: Barge
A37: Barge
A38: Barge
A39: Barge
A40: Barge
A41: Barge
A42: Barge
... A50: Barge
A51: Caravel | B51: Access To Foreign Data | C51: ATFD | D51: 1
A52: Caravel | B52: Cognitive Complexity | C52: CCC | D52: 5
A53: Caravel | B53: Coupling Between Objects | C53: CBO | D53: 5
A54: Caravel | B54: Data Abstraction Coupling | C54: DAC | D54: 0
A55: Caravel | B55: Depth Of Inheritance Tree | C55: DIT | D55: 2
A56: Caravel | B56: Halstead Difficulty | C56: CHD | D56: 30,0
A57: Caravel | B57: Halstead Effort | C57: CHEF | D57: 14268,0854
A58: Caravel | B58: Halstead Errors | C58: CHER | D58: 0,1961
A59: Caravel | B59: Halstead Length | C59: CHL | D59: 96
A60: Caravel | B60: Halstead Vocabulary | C60: CHVC | D60: 31
A61: Caravel | B61: Halstead Volume | C61: CHVL | D61: 475,6028
A62: Caravel | B62: Lack Of Cohesion Of Methods | C62: LCOM | D62: 0
... A79: Caravel | B79: Weighted Methods Per Class | C79: WMC | D79: 9
A80: Caravel
...

Sheet Method
A1: name6 | B1: name10 | C1: description11 | D1: name12 | E1: value13
A2: Fleet | B2: addShip(IShip) | C2: Cognitive Complexity | D2: CCM | E2: 3
A3: Fleet | B3: addShip(IShip) | C3: Condition Nesting Depth | D3: CND | E3: 1
A4: Fleet | B4: addShip(IShip) | C4: Coupling Dispersion | D4: CDISP | E4: 0,25
A5: Fleet | B5: addShip(IShip) | C5: Coupling Intensity | D5: CINT | E5: 2
A6: Fleet | B6: addShip(IShip) | C6: Foreign Data Providers | D6: FDP | E6: 0
A7: Fleet | B7: addShip(IShip) | C7: Halstead Difficulty | D7: HD | E7: 10,2857
A8: Fleet | B8: addShip(IShip) | C8: Halstead Effort | D8: HEF | E8: 1092,3242
A9: Fleet | B9: addShip(IShip) | C9: Halstead Errors | D9: HER | E9: 0,0354
A10: Fleet | B10: addShip(IShip) | C10: Halstead Length | D10: HL | E10: 25
A11: Fleet | B11: addShip(IShip) | C11: Halstead Vocabulary | D11: HVC | E11: 19
A12: Fleet | B12: addShip(IShip) | C12: Halstead Volume | D12: HVL | E12: 106,1982
... A3141: Compass | B3141: values() | C3141: Number Of Parameters | D3141: NOPM | E3141: 0
A3142: Barge
A3143: Barge
A3144: Barge
A3145: Barge
A3146: Barge
A3147: Barge
A3148: Barge
A3149: Barge
A3150: Barge
A3151: Barge
A3152: Barge
A3153: Barge
... A3792: Tasks

Sheet Game
A1: name6 | B1: name10 | C1: FullName | E1: description11 | F1: name12 | G1: value13
A2: Game | B2: fireShots(List<IPosition>) | C2: =CONCATENATE(A2,":",B2) -> Game:fireShots(List<IPosition>) | D2: =CONCATENATE(C2,F2) -> Game:fireShots(List<IPosition>)CCM | E2: Cognitive Complexity | F2: CCM | G2: 2
A3: Game | B3: fireShots(List<IPosition>) | C3: =CONCATENATE(A3,":",B3) -> Game:fireShots(List<IPosition>) | D3: =CONCATENATE(C3,F3) -> Game:fireShots(List<IPosition>)CND | E3: Condition Nesting Depth | F3: CND | G3: 1
A4: Game | B4: fireShots(List<IPosition>) | C4: =CONCATENATE(A4,":",B4) -> Game:fireShots(List<IPosition>) | D4: =CONCATENATE(C4,F4) -> Game:fireShots(List<IPosition>)CDISP | E4: Coupling Dispersion | F4: CDISP | G4: 0.4
A5: Game | B5: fireShots(List<IPosition>) | C5: =CONCATENATE(A5,":",B5) -> Game:fireShots(List<IPosition>) | D5: =CONCATENATE(C5,F5) -> Game:fireShots(List<IPosition>)CINT | E5: Coupling Intensity | F5: CINT | G5: 4
A6: Game | B6: fireShots(List<IPosition>) | C6: =CONCATENATE(A6,":",B6) -> Game:fireShots(List<IPosition>) | D6: =CONCATENATE(C6,F6) -> Game:fireShots(List<IPosition>)FDP | E6: Foreign Data Providers | F6: FDP | G6: 0
A7: Game | B7: fireShots(List<IPosition>) | C7: =CONCATENATE(A7,":",B7) -> Game:fireShots(List<IPosition>) | D7: =CONCATENATE(C7,F7) -> Game:fireShots(List<IPosition>)HD | E7: Halstead Difficulty | F7: HD | G7: 12.8333
A8: Game | B8: fireShots(List<IPosition>) | C8: =CONCATENATE(A8,":",B8) -> Game:fireShots(List<IPosition>) | D8: =CONCATENATE(C8,F8) -> Game:fireShots(List<IPosition>)HEF | E8: Halstead Effort | F8: HEF | G8: 2533.537
A9: Game | B9: fireShots(List<IPosition>) | C9: =CONCATENATE(A9,":",B9) -> Game:fireShots(List<IPosition>) | D9: =CONCATENATE(C9,F9) -> Game:fireShots(List<IPosition>)HER | E9: Halstead Errors | F9: HER | G9: 0.0619
A10: Game | B10: fireShots(List<IPosition>) | C10: =CONCATENATE(A10,":",B10) -> Game:fireShots(List<IPosition>) | D10: =CONCATENATE(C10,F10) -> Game:fireShots(List<IPosition>)HL | E10: Halstead Length | F10: HL | G10: 42
A11: Game | B11: fireShots(List<IPosition>) | C11: =CONCATENATE(A11,":",B11) -> Game:fireShots(List<IPosition>) | D11: =CONCATENATE(C11,F11) -> Game:fireShots(List<IPosition>)HVC | E11: Halstead Vocabulary | F11: HVC | G11: 26
A12: Game | B12: fireShots(List<IPosition>) | C12: =CONCATENATE(A12,":",B12) -> Game:fireShots(List<IPosition>) | D12: =CONCATENATE(C12,F12) -> Game:fireShots(List<IPosition>)HVL | E12: Halstead Volume | F12: HVL | G12: 197.4185
A13: Game | B13: fireShots(List<IPosition>) | C13: =CONCATENATE(A13,":",B13) -> Game:fireShots(List<IPosition>) | D13: =CONCATENATE(C13,F13) -> Game:fireShots(List<IPosition>)LOC | E13: Lines Of Code | F13: LOC | G13: 30
... A401: Game | B401: repeatedShot(IPosition) | C401: =CONCATENATE(A401,":",B401) -> Game:repeatedShot(IPosition) | D401: =CONCATENATE(C401,F401) -> Game:repeatedShot(IPosition)NOPM | E401: Number Of Parameters | F401: NOPM | G401: 1

Sheet Legenda
D1: Acronym | E1: Name
D2: CCM | E2: Cognitive Complexity
D3: CND | E3: Condition Nesting Depth
D4: CDISP | E4: Coupling Dispersion
D5: CINT | E5: Coupling Intensity
D6: FDP | E6: Foreign Data Providers
D7: HD | E7: Halstead Difficulty
D8: HEF | E8: Halstead Effort
D9: HER | E9: Halstead Errors
D10: HL | E10: Halstead Length
D11: HVC | E11: Halstead Vocabulary
D12: HVL | E12: Halstead Volume
... D21: NOPM | E21: Number Of Parameters

Sheet RESULTADO FINAL
A1: FullName | B1: CCM | C1: CND | D1: CDISP | E1: CINT | F1: FDP | G1: HD | H1: HEF | I1: HER | J1: HL | K1: HVC | L1: HVL | M1: LOC | N1: LAA | O1: LND | P1: MMI | Q1: MND | R1: CC | S1: NOAV | T1: NOL | U1: NOPM | V1: CCM | W1: CND | X1: CDISP | Y1: CINT | Z1: FDP | AA1: HD | AB1: HEF | AC1: HER | AD1: HL | AE1: HVC | AF1: HVL | AG1: LOC | AH1: LAA | AI1: LND | AJ1: MMI | AK1: MND | AL1: CC | AM1: NOAV | AN1: NOL | AO1: NOPM | AP1: SOMA | AV1: CCM | AW1: CND | AX1: CDISP | AY1: CINT | AZ1: FDP | BA1: HD | BB1: HEF | BC1: HER | BD1: HL | BE1: HVC | BF1: HVL | BG1: LOC | BH1: LAA | BI1: LND | BJ1: MMI | BK1: MND | BL1: CC | BM1: NOAV | BN1: NOL | BO1: NOPM
A2: Game:printBoard(IFleet, List<IMove>, boolean, boolean) | B2: =VLOOKUP(CONCATENATE($A2,B$1),Game!$D:$G,4,0) -> 19 | C2: =VLOOKUP(CONCATENATE($A2,C$1),Game!$D:$G,4,0) -> 3 | D2: =VLOOKUP(CONCATENATE($A2,D$1),Game!$D:$G,4,0) -> 0.5 | E2: =VLOOKUP(CONCATENATE($A2,E$1),Game!$D:$G,4,0) -> 12 | F2: =VLOOKUP(CONCATENATE($A2,F$1),Game!$D:$G,4,0) -> 1 | G2: =VLOOKUP(CONCATENATE($A2,G$1),Game!$D:$G,4,0) -> 45.2683 | H2: =VLOOKUP(CONCATENATE($A2,H$1),Game!$D:$G,4,0) -> 61319.141 | I2: =VLOOKUP(CONCATENATE($A2,I$1),Game!$D:$G,4,0) -> 0.5183 | ... U2: =VLOOKUP(CONCATENATE($A2,U$1),Game!$D:$G,4,0) -> 4 | V2: =(B2-MIN(B:B))/(MAX(B:B)-MIN(B:B)) -> 1 | W2: =(C2-MIN(C:C))/(MAX(C:C)-MIN(C:C)) -> 1 | X2: =(D2-MIN(D:D))/(MAX(D:D)-MIN(D:D)) -> 0.5 | Y2: =(E2-MIN(E:E))/(MAX(E:E)-MIN(E:E)) -> 0.85714286 | Z2: =(F2-MIN(F:F))/(MAX(F:F)-MIN(F:F)) -> 1 | AA2: =(G2-MIN(G:G))/(MAX(G:G)-MIN(G:G)) -> 1 | AB2: =(H2-MIN(H:H))/(MAX(H:H)-MIN(H:H)) -> 1 | AC2: =(I2-MIN(I:I))/(MAX(I:I)-MIN(I:I)) -> 1 | AD2: =(J2-MIN(J:J))/(MAX(J:J)-MIN(J:J)) -> 1 | AE2: =(K2-MIN(K:K))/(MAX(K:K)-MIN(K:K)) -> 1 | AF2: =(L2-MIN(L:L))/(MAX(L:L)-MIN(L:L)) -> 1 | AG2: =(M2-MIN(M:M))/(MAX(M:M)-MIN(M:M)) -> 1 | AH2: =(N2-MIN(N:N))/(MAX(N:N)-MIN(N:N)) -> 0.8571 | AI2: =(O2-MIN(O:O))/(MAX(O:O)-MIN(O:O)) -> 1 | AJ2: =(P2-MIN(P:P))/(MAX(P:P)-MIN(P:P)) -> 0 | AK2: =(Q2-MIN(Q:Q))/(MAX(Q:Q)-MIN(Q:Q)) -> 0.66666667 | AL2: =(R2-MIN(R:R))/(MAX(R:R)-MIN(R:R)) -> 1 | AM2: =(S2-MIN(S:S))/(MAX(S:S)-MIN(S:S)) -> 1 | AN2: =(T2-MIN(T:T))/(MAX(T:T)-MIN(T:T)) -> 1 | AO2: =(U2-MIN(U:U))/(MAX(U:U)-MIN(U:U)) -> 1 | AP2: =X2+AH2+Z2+AO2 -> 3.3571 | AU2: CCM | AV2: =CORREL($V:$V,V:V) -> 1 | AW2: =CORREL($V:$V,W:W) -> 0.93035005 | AX2: =CORREL($V:$V,X:X) -> 0.35734576 | AY2: =CORREL($V:$V,Y:Y) -> 0.85320894 | AZ2: =CORREL($V:$V,Z:Z) -> 0.5685059 | BA2: =CORREL($V:$V,AA:AA) -> 0.94578128 | BB2: =CORREL($V:$V,AB:AB) -> 0.96715038 | BC2: =CORREL($V:$V,AC:AC) -> 0.98992373 | BD2: =CORREL($V:$V,AD:AD) -> 0.9869189 | BE2: =CORREL($V:$V,AE:AE) -> 0.94948437 | BF2: =CORREL($V:$V,AF:AF) -> 0.98686114 | BG2: =CORREL($V:$V,AG:AG) -> 0.92099723 | BH2: =CORREL($V:$V,AH:AH) -> -0.038836356 | BI2: =CORREL($V:$V,AI:AI) -> 0.82982138 | BJ2: =CORREL($V:$V,AJ:AJ) -> -0.81395685 | BK2: =CORREL($V:$V,AK:AK) -> 0.79183639 | BL2: =CORREL($V:$V,AL:AL) -> 0.9947552 | BM2: =CORREL($V:$V,AM:AM) -> 0.92641613 | BN2: =CORREL($V:$V,AN:AN) -> 0.93306003 | BO2: =CORREL($V:$V,AO:AO) -> 0.66233838
A3: Game:randomEnemyFire() | B3: =VLOOKUP(CONCATENATE($A3,B$1),Game!$D:$G,4,0) -> 10 | C3: =VLOOKUP(CONCATENATE($A3,C$1),Game!$D:$G,4,0) -> 2 | D3: =VLOOKUP(CONCATENATE($A3,D$1),Game!$D:$G,4,0) -> 0.5625 | E3: =VLOOKUP(CONCATENATE($A3,E$1),Game!$D:$G,4,0) -> 14 | F3: =VLOOKUP(CONCATENATE($A3,F$1),Game!$D:$G,4,0) -> 1 | G3: =VLOOKUP(CONCATENATE($A3,G$1),Game!$D:$G,4,0) -> 43.4211 | H3: =VLOOKUP(CONCATENATE($A3,H$1),Game!$D:$G,4,0) -> 29011.797 | I3: =VLOOKUP(CONCATENATE($A3,I$1),Game!$D:$G,4,0) -> 0.3147 | ... U3: =VLOOKUP(CONCATENATE($A3,U$1),Game!$D:$G,4,0) -> 0 | V3: =(B3-MIN(B:B))/(MAX(B:B)-MIN(B:B)) -> 0.52631579 | W3: =(C3-MIN(C:C))/(MAX(C:C)-MIN(C:C)) -> 0.66666667 | X3: =(D3-MIN(D:D))/(MAX(D:D)-MIN(D:D)) -> 0.5625 | Y3: =(E3-MIN(E:E))/(MAX(E:E)-MIN(E:E)) -> 1 | Z3: =(F3-MIN(F:F))/(MAX(F:F)-MIN(F:F)) -> 1 | AA3: =(G3-MIN(G:G))/(MAX(G:G)-MIN(G:G)) -> 0.95827262 | AB3: =(H3-MIN(H:H))/(MAX(H:H)-MIN(H:H)) -> 0.47308705 | AC3: =(I3-MIN(I:I))/(MAX(I:I)-MIN(I:I)) -> 0.60649401 | AD3: =(J3-MIN(J:J))/(MAX(J:J)-MIN(J:J)) -> 0.53211009 | AE3: =(K3-MIN(K:K))/(MAX(K:K)-MIN(K:K)) -> 0.68656716 | AF3: =(L3-MIN(L:L))/(MAX(L:L)-MIN(L:L)) -> 0.49147092 | AG3: =(M3-MIN(M:M))/(MAX(M:M)-MIN(M:M)) -> 0.63636364 | AH3: =(N3-MIN(N:N))/(MAX(N:N)-MIN(N:N)) -> 0.8 | AI3: =(O3-MIN(O:O))/(MAX(O:O)-MIN(O:O)) -> 1 | AJ3: =(P3-MIN(P:P))/(MAX(P:P)-MIN(P:P)) -> 0.14424375 | AK3: =(Q3-MIN(Q:Q))/(MAX(Q:Q)-MIN(Q:Q)) -> 0.66666667 | AL3: =(R3-MIN(R:R))/(MAX(R:R)-MIN(R:R)) -> 0.47368421 | AM3: =(S3-MIN(S:S))/(MAX(S:S)-MIN(S:S)) -> 0.51851852 | AN3: =(T3-MIN(T:T))/(MAX(T:T)-MIN(T:T)) -> 0.5 | AO3: =(U3-MIN(U:U))/(MAX(U:U)-MIN(U:U)) -> 0 | AP3: =X3+AH3+Z3+AO3 -> 2.3625 | AU3: CND | AV3: =CORREL($W:$W,V:V) -> 0.93035005 | AW3: =CORREL($W:$W,W:W) -> 1 | AX3: =CORREL($W:$W,X:X) -> 0.43082148 | AY3: =CORREL($W:$W,Y:Y) -> 0.84156314 | AZ3: =CORREL($W:$W,Z:Z) -> 0.38018781 | BA3: =CORREL($W:$W,AA:AA) -> 0.92926813 | BB3: =CORREL($W:$W,AB:AB) -> 0.81981076 | BC3: =CORREL($W:$W,AC:AC) -> 0.88813404 | BD3: =CORREL($W:$W,AD:AD) -> 0.89090044 | BE3: =CORREL($W:$W,AE:AE) -> 0.91316885 | BF3: =CORREL($W:$W,AF:AF) -> 0.87501663 | BG3: =CORREL($W:$W,AG:AG) -> 0.88153871 | BH3: =CORREL($W:$W,AH:AH) -> 0.08358682 | BI3: =CORREL($W:$W,AI:AI) -> 0.78604072 | BJ3: =CORREL($W:$W,AJ:AJ) -> -0.84950507 | BK3: =CORREL($W:$W,AK:AK) -> 0.8820059 | BL3: =CORREL($W:$W,AL:AL) -> 0.9003531 | BM3: =CORREL($W:$W,AM:AM) -> 0.81936828 | BN3: =CORREL($W:$W,AN:AN) -> 0.76665444 | BO3: =CORREL($W:$W,AO:AO) -> 0.61196049
A4: Game:repeatedShot(IPosition) | B4: =VLOOKUP(CONCATENATE($A4,B$1),Game!$D:$G,4,0) -> 2 | C4: =VLOOKUP(CONCATENATE($A4,C$1),Game!$D:$G,4,0) -> 1 | D4: =VLOOKUP(CONCATENATE($A4,D$1),Game!$D:$G,4,0) -> 1 | E4: =VLOOKUP(CONCATENATE($A4,E$1),Game!$D:$G,4,0) -> 2 | F4: =VLOOKUP(CONCATENATE($A4,F$1),Game!$D:$G,4,0) -> 0 | G4: =VLOOKUP(CONCATENATE($A4,G$1),Game!$D:$G,4,0) -> 5.25 | H4: =VLOOKUP(CONCATENATE($A4,H$1),Game!$D:$G,4,0) -> 348.69 | I4: =VLOOKUP(CONCATENATE($A4,I$1),Game!$D:$G,4,0) -> 0.0165 | ... U4: =VLOOKUP(CONCATENATE($A4,U$1),Game!$D:$G,4,0) -> 1 | V4: =(B4-MIN(B:B))/(MAX(B:B)-MIN(B:B)) -> 0.10526316 | W4: =(C4-MIN(C:C))/(MAX(C:C)-MIN(C:C)) -> 0.33333333 | X4: =(D4-MIN(D:D))/(MAX(D:D)-MIN(D:D)) -> 1 | Y4: =(E4-MIN(E:E))/(MAX(E:E)-MIN(E:E)) -> 0.14285714 | Z4: =(F4-MIN(F:F))/(MAX(F:F)-MIN(F:F)) -> 0 | AA4: =(G4-MIN(G:G))/(MAX(G:G)-MIN(G:G)) -> 0.096005494 | AB4: =(H4-MIN(H:H))/(MAX(H:H)-MIN(H:H)) -> 0.0056093703 | AC4: =(I4-MIN(I:I))/(MAX(I:I)-MIN(I:I)) -> 0.030150754 | AD4: =(J4-MIN(J:J))/(MAX(J:J)-MIN(J:J)) -> 0.064220183 | AE4: =(K4-MIN(K:K))/(MAX(K:K)-MIN(K:K)) -> 0.17910448 | AF4: =(L4-MIN(L:L))/(MAX(L:L)-MIN(L:L)) -> 0.04568191 | AG4: =(M4-MIN(M:M))/(MAX(M:M)-MIN(M:M)) -> 0.060606061 | AH4: =(N4-MIN(N:N))/(MAX(N:N)-MIN(N:N)) -> 1 | AI4: =(O4-MIN(O:O))/(MAX(O:O)-MIN(O:O)) -> 0.5 | AJ4: =(P4-MIN(P:P))/(MAX(P:P)-MIN(P:P)) -> 0.69558592 | AK4: =(Q4-MIN(Q:Q))/(MAX(Q:Q)-MIN(Q:Q)) -> 0 | AL4: =(R4-MIN(R:R))/(MAX(R:R)-MIN(R:R)) -> 0.10526316 | AM4: =(S4-MIN(S:S))/(MAX(S:S)-MIN(S:S)) -> 0.074074074 | AN4: =(T4-MIN(T:T))/(MAX(T:T)-MIN(T:T)) -> 0.083333333 | AO4: =(U4-MIN(U:U))/(MAX(U:U)-MIN(U:U)) -> 0.25 | AP4: =X4+AH4+Z4+AO4 -> 2.25 | AU4: CDISP | AV4: =CORREL($X:$X,V:V) -> 0.35734576 | AW4: =CORREL($X:$X,W:W) -> 0.43082148 | AX4: =CORREL($X:$X,X:X) -> 1 | AY4: =CORREL($X:$X,Y:Y) -> 0.48083144 | AZ4: =CORREL($X:$X,Z:Z) -> 0.42178715 | BA4: =CORREL($X:$X,AA:AA) -> 0.42107565 | BB4: =CORREL($X:$X,AB:AB) -> 0.26365521 | BC4: =CORREL($X:$X,AC:AC) -> 0.327487 | BD4: =CORREL($X:$X,AD:AD) -> 0.34651271 | BE4: =CORREL($X:$X,AE:AE) -> 0.43381911 | BF4: =CORREL($X:$X,AF:AF) -> 0.32237132 | BG4: =CORREL($X:$X,AG:AG) -> 0.42114264 | BH4: =CORREL($X:$X,AH:AH) -> -0.36205403 | BI4: =CORREL($X:$X,AI:AI) -> 0.50244663 | BJ4: =CORREL($X:$X,AJ:AJ) -> -0.52647635 | BK4: =CORREL($X:$X,AK:AK) -> 0.35211897 | BL4: =CORREL($X:$X,AL:AL) -> 0.35268334 | BM4: =CORREL($X:$X,AM:AM) -> 0.31578823 | BN4: =CORREL($X:$X,AN:AN) -> 0.28996371 | BO4: =CORREL($X:$X,AO:AO) -> 0.19844494
A5: Game:fireSingleShot(IPosition, boolean) | B5: =VLOOKUP(CONCATENATE($A5,B$1),Game!$D:$G,4,0) -> 6 | C5: =VLOOKUP(CONCATENATE($A5,C$1),Game!$D:$G,4,0) -> 2 | D5: =VLOOKUP(CONCATENATE($A5,D$1),Game!$D:$G,4,0) -> 0.6 | E5: =VLOOKUP(CONCATENATE($A5,E$1),Game!$D:$G,4,0) -> 4 | F5: =VLOOKUP(CONCATENATE($A5,F$1),Game!$D:$G,4,0) -> 0 | G5: =VLOOKUP(CONCATENATE($A5,G$1),Game!$D:$G,4,0) -> 24.7273 | H5: =VLOOKUP(CONCATENATE($A5,H$1),Game!$D:$G,4,0) -> 7607.8577 | I5: =VLOOKUP(CONCATENATE($A5,I$1),Game!$D:$G,4,0) -> 0.1289 | ... U5: =VLOOKUP(CONCATENATE($A5,U$1),Game!$D:$G,4,0) -> 2 | V5: =(B5-MIN(B:B))/(MAX(B:B)-MIN(B:B)) -> 0.31578947 | W5: =(C5-MIN(C:C))/(MAX(C:C)-MIN(C:C)) -> 0.66666667 | X5: =(D5-MIN(D:D))/(MAX(D:D)-MIN(D:D)) -> 0.6 | Y5: =(E5-MIN(E:E))/(MAX(E:E)-MIN(E:E)) -> 0.28571429 | Z5: =(F5-MIN(F:F))/(MAX(F:F)-MIN(F:F)) -> 0 | AA5: =(G5-MIN(G:G))/(MAX(G:G)-MIN(G:G)) -> 0.53598851 | AB5: =(H5-MIN(H:H))/(MAX(H:H)-MIN(H:H)) -> 0.12400194 | AC5: =(I5-MIN(I:I))/(MAX(I:I)-MIN(I:I)) -> 0.2473908 | AD5: =(J5-MIN(J:J))/(MAX(J:J)-MIN(J:J)) -> 0.27981651 | AE5: =(K5-MIN(K:K))/(MAX(K:K)-MIN(K:K)) -> 0.37313433 | AF5: =(L5-MIN(L:L))/(MAX(L:L)-MIN(L:L)) -> 0.22441256 | AG5: =(M5-MIN(M:M))/(MAX(M:M)-MIN(M:M)) -> 0.43939394 | AH5: =(N5-MIN(N:N))/(MAX(N:N)-MIN(N:N)) -> 1 | AI5: =(O5-MIN(O:O))/(MAX(O:O)-MIN(O:O)) -> 0 | AJ5: =(P5-MIN(P:P))/(MAX(P:P)-MIN(P:P)) -> 0.27364635 | AK5: =(Q5-MIN(Q:Q))/(MAX(Q:Q)-MIN(Q:Q)) -> 0.66666667 | AL5: =(R5-MIN(R:R))/(MAX(R:R)-MIN(R:R)) -> 0.26315789 | AM5: =(S5-MIN(S:S))/(MAX(S:S)-MIN(S:S)) -> 0.25925926 | AN5: =(T5-MIN(T:T))/(MAX(T:T)-MIN(T:T)) -> 0 | AO5: =(U5-MIN(U:U))/(MAX(U:U)-MIN(U:U)) -> 0.5 | AP5: =X5+AH5+Z5+AO5 -> 2.1 | AU5: CINT | AV5: =CORREL($Y:$Y,V:V) -> 0.85320894 | AW5: =CORREL($Y:$Y,W:W) -> 0.84156314 | AX5: =CORREL($Y:$Y,X:X) -> 0.48083144 | AY5: =CORREL($Y:$Y,Y:Y) -> 1 | AZ5: =CORREL($Y:$Y,Z:Z) -> 0.64608166 | BA5: =CORREL($Y:$Y,AA:AA) -> 0.94240149 | BB5: =CORREL($Y:$Y,AB:AB) -> 0.76260395 | BC5: =CORREL($Y:$Y,AC:AC) -> 0.85465421 | BD5: =CORREL($Y:$Y,AD:AD) -> 0.84169859 | BE5: =CORREL($Y:$Y,AE:AE) -> 0.93298059 | BF5: =CORREL($Y:$Y,AF:AF) -> 0.82404023 | BG5: =CORREL($Y:$Y,AG:AG) -> 0.92071233 | BH5: =CORREL($Y:$Y,AH:AH) -> -0.24614771 | BI5: =CORREL($Y:$Y,AI:AI) -> 0.8967561 | BJ5: =CORREL($Y:$Y,AJ:AJ) -> -0.88964258 | BK5: =CORREL($Y:$Y,AK:AK) -> 0.90206372 | BL5: =CORREL($Y:$Y,AL:AL) -> 0.8151689 | BM5: =CORREL($Y:$Y,AM:AM) -> 0.78477534 | BN5: =CORREL($Y:$Y,AN:AN) -> 0.74126728 | BO5: =CORREL($Y:$Y,AO:AO) -> 0.39255646
A6: Game:getRemainingShips() | B6: =VLOOKUP(CONCATENATE($A6,B$1),Game!$D:$G,4,0) -> 0 | C6: =VLOOKUP(CONCATENATE($A6,C$1),Game!$D:$G,4,0) -> 0 | D6: =VLOOKUP(CONCATENATE($A6,D$1),Game!$D:$G,4,0) -> 1 | E6: =VLOOKUP(CONCATENATE($A6,E$1),Game!$D:$G,4,0) -> 2 | F6: =VLOOKUP(CONCATENATE($A6,F$1),Game!$D:$G,4,0) -> 0 | G6: =VLOOKUP(CONCATENATE($A6,G$1),Game!$D:$G,4,0) -> 2.5 | H6: =VLOOKUP(CONCATENATE($A6,H$1),Game!$D:$G,4,0) -> 49.1287 | I6: =VLOOKUP(CONCATENATE($A6,I$1),Game!$D:$G,4,0) -> 0.0045 | ... U6: =VLOOKUP(CONCATENATE($A6,U$1),Game!$D:$G,4,0) -> 0 | V6: =(B6-MIN(B:B))/(MAX(B:B)-MIN(B:B)) -> 0 | W6: =(C6-MIN(C:C))/(MAX(C:C)-MIN(C:C)) -> 0 | X6: =(D6-MIN(D:D))/(MAX(D:D)-MIN(D:D)) -> 1 | Y6: =(E6-MIN(E:E))/(MAX(E:E)-MIN(E:E)) -> 0.14285714 | Z6: =(F6-MIN(F:F))/(MAX(F:F)-MIN(F:F)) -> 0 | AA6: =(G6-MIN(G:G))/(MAX(G:G)-MIN(G:G)) -> 0.033884292 | AB6: =(H6-MIN(H:H))/(MAX(H:H)-MIN(H:H)) -> 0.00072370944 | AC6: =(I6-MIN(I:I))/(MAX(I:I)-MIN(I:I)) -> 0.0069578663 | AD6: =(J6-MIN(J:J))/(MAX(J:J)-MIN(J:J)) -> 0.018348624 | AE6: =(K6-MIN(K:K))/(MAX(K:K)-MIN(K:K)) -> 0.059701493 | AF6: =(L6-MIN(L:L))/(MAX(L:L)-MIN(L:L)) -> 0.011036018 | AG6: =(M6-MIN(M:M))/(MAX(M:M)-MIN(M:M)) -> 0.03030303 | AH6: =(N6-MIN(N:N))/(MAX(N:N)-MIN(N:N)) -> 1 | AI6: =(O6-MIN(O:O))/(MAX(O:O)-MIN(O:O)) -> 0 | AJ6: =(P6-MIN(P:P))/(MAX(P:P)-MIN(P:P)) -> 0.85004615 | AK6: =(Q6-MIN(Q:Q))/(MAX(Q:Q)-MIN(Q:Q)) -> 0 | AL6: =(R6-MIN(R:R))/(MAX(R:R)-MIN(R:R)) -> 0 | AM6: =(S6-MIN(S:S))/(MAX(S:S)-MIN(S:S)) -> 0.037037037 | AN6: =(T6-MIN(T:T))/(MAX(T:T)-MIN(T:T)) -> 0 | AO6: =(U6-MIN(U:U))/(MAX(U:U)-MIN(U:U)) -> 0 | AP6: =X6+AH6+Z6+AO6 -> 2 | AU6: FDP | AV6: =CORREL($Z:$Z,V:V) -> 0.5685059 | AW6: =CORREL($Z:$Z,W:W) -> 0.38018781 | AX6: =CORREL($Z:$Z,X:X) -> 0.42178715 | AY6: =CORREL($Z:$Z,Y:Y) -> 0.64608166 | AZ6: =CORREL($Z:$Z,Z:Z) -> 1 | BA6: =CORREL($Z:$Z,AA:AA) -> 0.62223793 | BB6: =CORREL($Z:$Z,AB:AB) -> 0.61456317 | BC6: =CORREL($Z:$Z,AC:AC) -> 0.63032357 | BD6: =CORREL($Z:$Z,AD:AD) -> 0.62283396 | BE6: =CORREL($Z:$Z,AE:AE) -> 0.60601929 | BF6: =CORREL($Z:$Z,AF:AF) -> 0.61735904 | BG6: =CORREL($Z:$Z,AG:AG) -> 0.61602232 | BH6: =CORREL($Z:$Z,AH:AH) -> -0.78403007 | BI6: =CORREL($Z:$Z,AI:AI) -> 0.64071161 | BJ6: =CORREL($Z:$Z,AJ:AJ) -> -0.56256049 | BK6: =CORREL($Z:$Z,AK:AK) -> 0.38018781 | BL6: =CORREL($Z:$Z,AL:AL) -> 0.58729592 | BM6: =CORREL($Z:$Z,AM:AM) -> 0.58792257 | BN6: =CORREL($Z:$Z,AN:AN) -> 0.64563859 | BO6: =CORREL($Z:$Z,AO:AO) -> 0.23973165
A7: Game:jsonShots(List<IPosition>) | B7: =VLOOKUP(CONCATENATE($A7,B$1),Game!$D:$G,4,0) -> 2 | C7: =VLOOKUP(CONCATENATE($A7,C$1),Game!$D:$G,4,0) -> 0 | D7: =VLOOKUP(CONCATENATE($A7,D$1),Game!$D:$G,4,0) -> 0.7143 | E7: =VLOOKUP(CONCATENATE($A7,E$1),Game!$D:$G,4,0) -> 7 | F7: =VLOOKUP(CONCATENATE($A7,F$1),Game!$D:$G,4,0) -> 1 | G7: =VLOOKUP(CONCATENATE($A7,G$1),Game!$D:$G,4,0) -> 14.1667 | H7: =VLOOKUP(CONCATENATE($A7,H$1),Game!$D:$G,4,0) -> 2821.6773 | I7: =VLOOKUP(CONCATENATE($A7,I$1),Game!$D:$G,4,0) -> 0.0666 | ... U7: =VLOOKUP(CONCATENATE($A7,U$1),Game!$D:$G,4,0) -> 1 | V7: =(B7-MIN(B:B))/(MAX(B:B)-MIN(B:B)) -> 0.10526316 | W7: =(C7-MIN(C:C))/(MAX(C:C)-MIN(C:C)) -> 0 | X7: =(D7-MIN(D:D))/(MAX(D:D)-MIN(D:D)) -> 0.7143 | Y7: =(E7-MIN(E:E))/(MAX(E:E)-MIN(E:E)) -> 0.5 | Z7: =(F7-MIN(F:F))/(MAX(F:F)-MIN(F:F)) -> 1 | AA7: =(G7-MIN(G:G))/(MAX(G:G)-MIN(G:G)) -> 0.29742954 | AB7: =(H7-MIN(H:H))/(MAX(H:H)-MIN(H:H)) -> 0.045942275 | AC7: =(I7-MIN(I:I))/(MAX(I:I)-MIN(I:I)) -> 0.12698106 | AD7: =(J7-MIN(J:J))/(MAX(J:J)-MIN(J:J)) -> 0.17431193 | AE7: =(K7-MIN(K:K))/(MAX(K:K)-MIN(K:K)) -> 0.3880597 | AF7: =(L7-MIN(L:L))/(MAX(L:L)-MIN(L:L)) -> 0.14403609 | AG7: =(M7-MIN(M:M))/(MAX(M:M)-MIN(M:M)) -> 0.51515152 | AH7: =(N7-MIN(N:N))/(MAX(N:N)-MIN(N:N)) -> 0 | AI7: =(O7-MIN(O:O))/(MAX(O:O)-MIN(O:O)) -> 0.5 | AJ7: =(P7-MIN(P:P))/(MAX(P:P)-MIN(P:P)) -> 0.27538813 | AK7: =(Q7-MIN(Q:Q))/(MAX(Q:Q)-MIN(Q:Q)) -> 0.33333333 | AL7: =(R7-MIN(R:R))/(MAX(R:R)-MIN(R:R)) -> 0.10526316 | AM7: =(S7-MIN(S:S))/(MAX(S:S)-MIN(S:S)) -> 0.25925926 | AN7: =(T7-MIN(T:T))/(MAX(T:T)-MIN(T:T)) -> 0.083333333 | AO7: =(U7-MIN(U:U))/(MAX(U:U)-MIN(U:U)) -> 0.25 | AP7: =X7+AH7+Z7+AO7 -> 1.9643 | AU7: HD | AV7: =CORREL($AA:$AA,V:V) -> 0.94578128 | AW7: =CORREL($AA:$AA,W:W) -> 0.92926813 | AX7: =CORREL($AA:$AA,X:X) -> 0.42107565 | AY7: =CORREL($AA:$AA,Y:Y) -> 0.94240149 | AZ7: =CORREL($AA:$AA,Z:Z) -> 0.62223793 | BA7: =CORREL($AA:$AA,AA:AA) -> 1 | BB7: =CORREL($AA:$AA,AB:AB) -> 0.87375341 | BC7: =CORREL($AA:$AA,AC:AC) -> 0.94774176 | BD7: =CORREL($AA:$AA,AD:AD) -> 0.93700171 | BE7: =CORREL($AA:$AA,AE:AE) -> 0.96305376 | BF7: =CORREL($AA:$AA,AF:AF) -> 0.92036127 | BG7: =CORREL($AA:$AA,AG:AG) -> 0.94721914 | BH7: =CORREL($AA:$AA,AH:AH) -> -0.13253455 | BI7: =CORREL($AA:$AA,AI:AI) -> 0.86464224 | BJ7: =CORREL($AA:$AA,AJ:AJ) -> -0.8970562 | BK7: =CORREL($AA:$AA,AK:AK) -> 0.88848527 | BL7: =CORREL($AA:$AA,AL:AL) -> 0.92068794 | BM7: =CORREL($AA:$AA,AM:AM) -> 0.87777901 | BN7: =CORREL($AA:$AA,AN:AN) -> 0.83504555 | BO7: =CORREL($AA:$AA,AO:AO) -> 0.53520025
A8: Game:fireShots(List<IPosition>) | B8: =VLOOKUP(CONCATENATE($A8,B$1),Game!$D:$G,4,0) -> 2 | C8: =VLOOKUP(CONCATENATE($A8,C$1),Game!$D:$G,4,0) -> 1 | D8: =VLOOKUP(CONCATENATE($A8,D$1),Game!$D:$G,4,0) -> 0.4 | E8: =VLOOKUP(CONCATENATE($A8,E$1),Game!$D:$G,4,0) -> 4 | F8: =VLOOKUP(CONCATENATE($A8,F$1),Game!$D:$G,4,0) -> 0 | G8: =VLOOKUP(CONCATENATE($A8,G$1),Game!$D:$G,4,0) -> 12.8333 | H8: =VLOOKUP(CONCATENATE($A8,H$1),Game!$D:$G,4,0) -> 2533.537 | I8: =VLOOKUP(CONCATENATE($A8,I$1),Game!$D:$G,4,0) -> 0.0619 | ... U8: =VLOOKUP(CONCATENATE($A8,U$1),Game!$D:$G,4,0) -> 1 | V8: =(B8-MIN(B:B))/(MAX(B:B)-MIN(B:B)) -> 0.10526316 | W8: =(C8-MIN(C:C))/(MAX(C:C)-MIN(C:C)) -> 0.33333333 | X8: =(D8-MIN(D:D))/(MAX(D:D)-MIN(D:D)) -> 0.4 | Y8: =(E8-MIN(E:E))/(MAX(E:E)-MIN(E:E)) -> 0.28571429 | Z8: =(F8-MIN(F:F))/(MAX(F:F)-MIN(F:F)) -> 0 | AA8: =(G8-MIN(G:G))/(MAX(G:G)-MIN(G:G)) -> 0.26730866 | AB8: =(H8-MIN(H:H))/(MAX(H:H)-MIN(H:H)) -> 0.041242884 | AC8: =(I8-MIN(I:I))/(MAX(I:I)-MIN(I:I)) -> 0.11789718 | AD8: =(J8-MIN(J:J))/(MAX(J:J)-MIN(J:J)) -> 0.17889908 | AE8: =(K8-MIN(K:K))/(MAX(K:K)-MIN(K:K)) -> 0.34328358 | AF8: =(L8-MIN(L:L))/(MAX(L:L)-MIN(L:L)) -> 0.14273317 | AG8: =(M8-MIN(M:M))/(MAX(M:M)-MIN(M:M)) -> 0.39393939 | AH8: =(N8-MIN(N:N))/(MAX(N:N)-MIN(N:N)) -> 1 | AI8: =(O8-MIN(O:O))/(MAX(O:O)-MIN(O:O)) -> 0.5 | AJ8: =(P8-MIN(P:P))/(MAX(P:P)-MIN(P:P)) -> 0.32804071 | AK8: =(Q8-MIN(Q:Q))/(MAX(Q:Q)-MIN(Q:Q)) -> 0.33333333 | AL8: =(R8-MIN(R:R))/(MAX(R:R)-MIN(R:R)) -> 0.10526316 | AM8: =(S8-MIN(S:S))/(MAX(S:S)-MIN(S:S)) -> 0.25925926 | AN8: =(T8-MIN(T:T))/(MAX(T:T)-MIN(T:T)) -> 0.083333333 | AO8: =(U8-MIN(U:U))/(MAX(U:U)-MIN(U:U)) -> 0.25 | AP8: =X8+AH8+Z8+AO8 -> 1.65 | AU8: HEF | AV8: =CORREL($AB:$AB,V:V) -> 0.96715038 | AW8: =CORREL($AB:$AB,W:W) -> 0.81981076 | AX8: =CORREL($AB:$AB,X:X) -> 0.26365521 | AY8: =CORREL($AB:$AB,Y:Y) -> 0.76260395 | AZ8: =CORREL($AB:$AB,Z:Z) -> 0.61456317 | BA8: =CORREL($AB:$AB,AA:AA) -> 0.87375341 | BB8: =CORREL($AB:$AB,AB:AB) -> 1 | BC8: =CORREL($AB:$AB,AC:AC) -> 0.98287025 | BD8: =CORREL($AB:$AB,AD:AD) -> 0.97415566 | BE8: =CORREL($AB:$AB,AE:AE) -> 0.88214097 | BF8: =CORREL($AB:$AB,AF:AF) -> 0.98579454 | BG8: =CORREL($AB:$AB,AG:AG) -> 0.84649702 | BH8: =CORREL($AB:$AB,AH:AH) -> -0.049112571 | BI8: =CORREL($AB:$AB,AI:AI) -> 0.79000024 | BJ8: =CORREL($AB:$AB,AJ:AJ) -> -0.69903081 | BK8: =CORREL($AB:$AB,AK:AK) -> 0.633273 | BL8: =CORREL($AB:$AB,AL:AL) -> 0.9830733 | BM8: =CORREL($AB:$AB,AM:AM) -> 0.92512215 | BN8: =CORREL($AB:$AB,AN:AN) -> 0.98614799 | BO8: =CORREL($AB:$AB,AO:AO) -> 0.63788484
A9: Game:readEnemyFire(Scanner) | B9: =VLOOKUP(CONCATENATE($A9,B$1),Game!$D:$G,4,0) -> 7 | C9: =VLOOKUP(CONCATENATE($A9,C$1),Game!$D:$G,4,0) -> 2 | D9: =VLOOKUP(CONCATENATE($A9,D$1),Game!$D:$G,4,0) -> 0.2857 | E9: =VLOOKUP(CONCATENATE($A9,E$1),Game!$D:$G,4,0) -> 12 | F9: =VLOOKUP(CONCATENATE($A9,F$1),Game!$D:$G,4,0) -> 0 | G9: =VLOOKUP(CONCATENATE($A9,G$1),Game!$D:$G,4,0) -> 26.1 | H9: =VLOOKUP(CONCATENATE($A9,H$1),Game!$D:$G,4,0) -> 9570.285 | I9: =VLOOKUP(CONCATENATE($A9,I$1),Game!$D:$G,4,0) -> 0.1503 | ... U9: =VLOOKUP(CONCATENATE($A9,U$1),Game!$D:$G,4,0) -> 1 | V9: =(B9-MIN(B:B))/(MAX(B:B)-MIN(B:B)) -> 0.36842105 | W9: =(C9-MIN(C:C))/(MAX(C:C)-MIN(C:C)) -> 0.66666667 | X9: =(D9-MIN(D:D))/(MAX(D:D)-MIN(D:D)) -> 0.2857 | Y9: =(E9-MIN(E:E))/(MAX(E:E)-MIN(E:E)) -> 0.85714286 | Z9: =(F9-MIN(F:F))/(MAX(F:F)-MIN(F:F)) -> 0 | AA9: =(G9-MIN(G:G))/(MAX(G:G)-MIN(G:G)) -> 0.56699715 | AB9: =(H9-MIN(H:H))/(MAX(H:H)-MIN(H:H)) -> 0.15600792 | AC9: =(I9-MIN(I:I))/(MAX(I:I)-MIN(I:I)) -> 0.28875145 | AD9: =(J9-MIN(J:J))/(MAX(J:J)-MIN(J:J)) -> 0.29816514 | AE9: =(K9-MIN(K:K))/(MAX(K:K)-MIN(K:K)) -> 0.58208955 | AF9: =(L9-MIN(L:L))/(MAX(L:L)-MIN(L:L)) -> 0.26812731 | AG9: =(M9-MIN(M:M))/(MAX(M:M)-MIN(M:M)) -> 0.57575758 | AH9: =(N9-MIN(N:N))/(MAX(N:N)-MIN(N:N)) -> 1 | AI9: =(O9-MIN(O:O))/(MAX(O:O)-MIN(O:O)) -> 0.5 | AJ9: =(P9-MIN(P:P))/(MAX(P:P)-MIN(P:P)) -> 0.20826086 | AK9: =(Q9-MIN(Q:Q))/(MAX(Q:Q)-MIN(Q:Q)) -> 1 | AL9: =(R9-MIN(R:R))/(MAX(R:R)-MIN(R:R)) -> 0.26315789 | AM9: =(S9-MIN(S:S))/(MAX(S:S)-MIN(S:S)) -> 0.25925926 | AN9: =(T9-MIN(T:T))/(MAX(T:T)-MIN(T:T)) -> 0.083333333 | AO9: =(U9-MIN(U:U))/(MAX(U:U)-MIN(U:U)) -> 0.25 | AP9: =X9+AH9+Z9+AO9 -> 1.5357 | AU9: HER | AV9: =CORREL($AC:$AC,V:V) -> 0.98992373 | AW9: =CORREL($AC:$AC,W:W) -> 0.88813404 | AX9: =CORREL($AC:$AC,X:X) -> 0.327487 | AY9: =CORREL($AC:$AC,Y:Y) -> 0.85465421 | AZ9: =CORREL($AC:$AC,Z:Z) -> 0.63032357 | BA9: =CORREL($AC:$AC,AA:AA) -> 0.94774176 | BB9: =CORREL($AC:$AC,AB:AB) -> 0.98287025 | BC9: =CORREL($AC:$AC,AC:AC) -> 1 | BD9: =CORREL($AC:$AC,AD:AD) -> 0.99235249 | BE9: =CORREL($AC:$AC,AE:AE) -> 0.94410161 | BF9: =CORREL($AC:$AC,AF:AF) -> 0.9934178 | BG9: =CORREL($AC:$AC,AG:AG) -> 0.9159573 | BH9: =CORREL($AC:$AC,AH:AH) -> -0.078455403 | BI9: =CORREL($AC:$AC,AI:AI) -> 0.84337015 | BJ9: =CORREL($AC:$AC,AJ:AJ) -> -0.80174498 | BK9: =CORREL($AC:$AC,AK:AK) -> 0.75368714 | BL9: =CORREL($AC:$AC,AL:AL) -> 0.99070163 | BM9: =CORREL($AC:$AC,AM:AM) -> 0.94146277 | BN9: =CORREL($AC:$AC,AN:AN) -> 0.95878557 | BO9: =CORREL($AC:$AC,AO:AO) -> 0.62759103
A10: Game:printAlienBoard(boolean, boolean) | B10: =VLOOKUP(CONCATENATE($A10,B$1),Game!$D:$G,4,0) -> 0 | C10: =VLOOKUP(CONCATENATE($A10,C$1),Game!$D:$G,4,0) -> 0 | D10: =VLOOKUP(CONCATENATE($A10,D$1),Game!$D:$G,4,0) -> 0 | E10: =VLOOKUP(CONCATENATE($A10,E$1),Game!$D:$G,4,0) -> 0 | F10: =VLOOKUP(CONCATENATE($A10,F$1),Game!$D:$G,4,0) -> 0 | G10: =VLOOKUP(CONCATENATE($A10,G$1),Game!$D:$G,4,0) -> 2.5 | H10: =VLOOKUP(CONCATENATE($A10,H$1),Game!$D:$G,4,0) -> 87.1729 | I10: =VLOOKUP(CONCATENATE($A10,I$1),Game!$D:$G,4,0) -> 0.0066 | ... U10: =VLOOKUP(CONCATENATE($A10,U$1),Game!$D:$G,4,0) -> 2 | V10: =(B10-MIN(B:B))/(MAX(B:B)-MIN(B:B)) -> 0 | W10: =(C10-MIN(C:C))/(MAX(C:C)-MIN(C:C)) -> 0 | X10: =(D10-MIN(D:D))/(MAX(D:D)-MIN(D:D)) -> 0 | Y10: =(E10-MIN(E:E))/(MAX(E:E)-MIN(E:E)) -> 0 | Z10: =(F10-MIN(F:F))/(MAX(F:F)-MIN(F:F)) -> 0 | AA10: =(G10-MIN(G:G))/(MAX(G:G)-MIN(G:G)) -> 0.033884292 | AB10: =(H10-MIN(H:H))/(MAX(H:H)-MIN(H:H)) -> 0.001344187 | AC10: =(I10-MIN(I:I))/(MAX(I:I)-MIN(I:I)) -> 0.011016622 | AD10: =(J10-MIN(J:J))/(MAX(J:J)-MIN(J:J)) -> 0.036697248 | AE10: =(K10-MIN(K:K))/(MAX(K:K)-MIN(K:K)) -> 0.089552239 | AF10: =(L10-MIN(L:L))/(MAX(L:L)-MIN(L:L)) -> 0.02230992 | AG10: =(M10-MIN(M:M))/(MAX(M:M)-MIN(M:M)) -> 0 | AH10: =(N10-MIN(N:N))/(MAX(N:N)-MIN(N:N)) -> 1 | AI10: =(O10-MIN(O:O))/(MAX(O:O)-MIN(O:O)) -> 0 | AJ10: =(P10-MIN(P:P))/(MAX(P:P)-MIN(P:P)) -> 0.89809261 | AK10: =(Q10-MIN(Q:Q))/(MAX(Q:Q)-MIN(Q:Q)) -> 0 | AL10: =(R10-MIN(R:R))/(MAX(R:R)-MIN(R:R)) -> 0 | AM10: =(S10-MIN(S:S))/(MAX(S:S)-MIN(S:S)) -> 0.11111111 | AN10: =(T10-MIN(T:T))/(MAX(T:T)-MIN(T:T)) -> 0 | AO10: =(U10-MIN(U:U))/(MAX(U:U)-MIN(U:U)) -> 0.5 | AP10: =X10+AH10+Z10+AO10 -> 1.5 | AU10: HL | AV10: =CORREL($AD:$AD,V:V) -> 0.9869189 | AW10: =CORREL($AD:$AD,W:W) -> 0.89090044 | AX10: =CORREL($AD:$AD,X:X) -> 0.34651271 | AY10: =CORREL($AD:$AD,Y:Y) -> 0.84169859 | AZ10: =CORREL($AD:$AD,Z:Z) -> 0.62283396 | BA10: =CORREL($AD:$AD,AA:AA) -> 0.93700171 | BB10: =CORREL($AD:$AD,AB:AB) -> 0.97415566 | BC10: =CORREL($AD:$AD,AC:AC) -> 0.99235249 | BD10: =CORREL($AD:$AD,AD:AD) -> 1 | BE10: =CORREL($AD:$AD,AE:AE) -> 0.95907996 | BF10: =CORREL($AD:$AD,AF:AF) -> 0.99771818 | BG10: =CORREL($AD:$AD,AG:AG) -> 0.93397053 | BH10: =CORREL($AD:$AD,AH:AH) -> -0.097860912 | BI10: =CORREL($AD:$AD,AI:AI) -> 0.83810654 | BJ10: =CORREL($AD:$AD,AJ:AJ) -> -0.83888277 | BK10: =CORREL($AD:$AD,AK:AK) -> 0.75621609 | BL10: =CORREL($AD:$AD,AL:AL) -> 0.98991922 | BM10: =CORREL($AD:$AD,AM:AM) -> 0.9699008 | BN10: =CORREL($AD:$AD,AN:AN) -> 0.94958233 | BO10: =CORREL($AD:$AD,AO:AO) -> 0.68803806
A11: Game:printMyBoard(boolean, boolean) | B11: =VLOOKUP(CONCATENATE($A11,B$1),Game!$D:$G,4,0) -> 0 | C11: =VLOOKUP(CONCATENATE($A11,C$1),Game!$D:$G,4,0) -> 0 | D11: =VLOOKUP(CONCATENATE($A11,D$1),Game!$D:$G,4,0) -> 0 | E11: =VLOOKUP(CONCATENATE($A11,E$1),Game!$D:$G,4,0) -> 0 | F11: =VLOOKUP(CONCATENATE($A11,F$1),Game!$D:$G,4,0) -> 0 | G11: =VLOOKUP(CONCATENATE($A11,G$1),Game!$D:$G,4,0) -> 2.5 | H11: =VLOOKUP(CONCATENATE($A11,H$1),Game!$D:$G,4,0) -> 87.1729 | I11: =VLOOKUP(CONCATENATE($A11,I$1),Game!$D:$G,4,0) -> 0.0066 | ... U11: =VLOOKUP(CONCATENATE($A11,U$1),Game!$D:$G,4,0) -> 2 | V11: =(B11-MIN(B:B))/(MAX(B:B)-MIN(B:B)) -> 0 | W11: =(C11-MIN(C:C))/(MAX(C:C)-MIN(C:C)) -> 0 | X11: =(D11-MIN(D:D))/(MAX(D:D)-MIN(D:D)) -> 0 | Y11: =(E11-MIN(E:E))/(MAX(E:E)-MIN(E:E)) -> 0 | Z11: =(F11-MIN(F:F))/(MAX(F:F)-MIN(F:F)) -> 0 | AA11: =(G11-MIN(G:G))/(MAX(G:G)-MIN(G:G)) -> 0.033884292 | AB11: =(H11-MIN(H:H))/(MAX(H:H)-MIN(H:H)) -> 0.001344187 | AC11: =(I11-MIN(I:I))/(MAX(I:I)-MIN(I:I)) -> 0.011016622 | AD11: =(J11-MIN(J:J))/(MAX(J:J)-MIN(J:J)) -> 0.036697248 | AE11: =(K11-MIN(K:K))/(MAX(K:K)-MIN(K:K)) -> 0.089552239 | AF11: =(L11-MIN(L:L))/(MAX(L:L)-MIN(L:L)) -> 0.02230992 | AG11: =(M11-MIN(M:M))/(MAX(M:M)-MIN(M:M)) -> 0 | AH11: =(N11-MIN(N:N))/(MAX(N:N)-MIN(N:N)) -> 1 | AI11: =(O11-MIN(O:O))/(MAX(O:O)-MIN(O:O)) -> 0 | AJ11: =(P11-MIN(P:P))/(MAX(P:P)-MIN(P:P)) -> 0.89809261 | AK11: =(Q11-MIN(Q:Q))/(MAX(Q:Q)-MIN(Q:Q)) -> 0 | AL11: =(R11-MIN(R:R))/(MAX(R:R)-MIN(R:R)) -> 0 | AM11: =(S11-MIN(S:S))/(MAX(S:S)-MIN(S:S)) -> 0.11111111 | AN11: =(T11-MIN(T:T))/(MAX(T:T)-MIN(T:T)) -> 0 | AO11: =(U11-MIN(U:U))/(MAX(U:U)-MIN(U:U)) -> 0.5 | AP11: =X11+AH11+Z11+AO11 -> 1.5 | AU11: HVC | AV11: =CORREL($AE:$AE,V:V) -> 0.94948437 | AW11: =CORREL($AE:$AE,W:W) -> 0.91316885 | AX11: =CORREL($AE:$AE,X:X) -> 0.43381911 | AY11: =CORREL($AE:$AE,Y:Y) -> 0.93298059 | AZ11: =CORREL($AE:$AE,Z:Z) -> 0.60601929 | BA11: =CORREL($AE:$AE,AA:AA) -> 0.96305376 | BB11: =CORREL($AE:$AE,AB:AB) -> 0.88214097 | BC11: =CORREL($AE:$AE,AC:AC) -> 0.94410161 | BD11: =CORREL($AE:$AE,AD:AD) -> 0.95907996 | BE11: =CORREL($AE:$AE,AE:AE) -> 1 | BF11: =CORREL($AE:$AE,AF:AF) -> 0.94406295 | BG11: =CORREL($AE:$AE,AG:AG) -> 0.98190476 | BH11: =CORREL($AE:$AE,AH:AH) -> -0.150433 | BI11: =CORREL($AE:$AE,AI:AI) -> 0.89813774 | BJ11: =CORREL($AE:$AE,AJ:AJ) -> -0.94174696 | BK11: =CORREL($AE:$AE,AK:AK) -> 0.87099015 | BL11: =CORREL($AE:$AE,AL:AL) -> 0.93270907 | BM11: =CORREL($AE:$AE,AM:AM) -> 0.94073433 | BN11: =CORREL($AE:$AE,AN:AN) -> 0.85777309 | BO11: =CORREL($AE:$AE,AO:AO) -> 0.65293789
A12: Game:over() | B12: =VLOOKUP(CONCATENATE($A12,B$1),Game!$D:$G,4,0) -> 0 | C12: =VLOOKUP(CONCATENATE($A12,C$1),Game!$D:$G,4,0) -> 0 | D12: =VLOOKUP(CONCATENATE($A12,D$1),Game!$D:$G,4,0) -> 0.5 | E12: =VLOOKUP(CONCATENATE($A12,E$1),Game!$D:$G,4,0) -> 2 | F12: =VLOOKUP(CONCATENATE($A12,F$1),Game!$D:$G,4,0) -> 1 | G12: =VLOOKUP(CONCATENATE($A12,G$1),Game!$D:$G,4,0) -> 4.6667 | H12: =VLOOKUP(CONCATENATE($A12,H$1),Game!$D:$G,4,0) -> 170.3129 | I12: =VLOOKUP(CONCATENATE($A12,I$1),Game!$D:$G,4,0) -> 0.0102 | ... U12: =VLOOKUP(CONCATENATE($A12,U$1),Game!$D:$G,4,0) -> 0 | V12: =(B12-MIN(B:B))/(MAX(B:B)-MIN(B:B)) -> 0 | W12: =(C12-MIN(C:C))/(MAX(C:C)-MIN(C:C)) -> 0 | X12: =(D12-MIN(D:D))/(MAX(D:D)-MIN(D:D)) -> 0.5 | Y12: =(E12-MIN(E:E))/(MAX(E:E)-MIN(E:E)) -> 0.14285714 | Z12: =(F12-MIN(F:F))/(MAX(F:F)-MIN(F:F)) -> 1 | AA12: =(G12-MIN(G:G))/(MAX(G:G)-MIN(G:G)) -> 0.082829022 | AB12: =(H12-MIN(H:H))/(MAX(H:H)-MIN(H:H)) -> 0.0027001493 | AC12: =(I12-MIN(I:I))/(MAX(I:I)-MIN(I:I)) -> 0.017974488 | AD12: =(J12-MIN(J:J))/(MAX(J:J)-MIN(J:J)) -> 0.04587156 | AE12: =(K12-MIN(K:K))/(MAX(K:K)-MIN(K:K)) -> 0.059701493 | AF12: =(L12-MIN(L:L))/(MAX(L:L)-MIN(L:L)) -> 0.023514824 | AG12: =(M12-MIN(M:M))/(MAX(M:M)-MIN(M:M)) -> 0.03030303 | AH12: =(N12-MIN(N:N))/(MAX(N:N)-MIN(N:N)) -> 0 | AI12: =(O12-MIN(O:O))/(MAX(O:O)-MIN(O:O)) -> 0 | AJ12: =(P12-MIN(P:P))/(MAX(P:P)-MIN(P:P)) -> 0.80497303 | AK12: =(Q12-MIN(Q:Q))/(MAX(Q:Q)-MIN(Q:Q)) -> 0 | AL12: =(R12-MIN(R:R))/(MAX(R:R)-MIN(R:R)) -> 0 | AM12: =(S12-MIN(S:S))/(MAX(S:S)-MIN(S:S)) -> 0 | AN12: =(T12-MIN(T:T))/(MAX(T:T)-MIN(T:T)) -> 0 | AO12: =(U12-MIN(U:U))/(MAX(U:U)-MIN(U:U)) -> 0 | AP12: =X12+AH12+Z12+AO12 -> 1.5 | AU12: HVL | AV12: =CORREL($AF:$AF,V:V) -> 0.98686114 | AW12: =CORREL($AF:$AF,W:W) -> 0.87501663 | AX12: =CORREL($AF:$AF,X:X) -> 0.32237132 | AY12: =CORREL($AF:$AF,Y:Y) -> 0.82404023 | AZ12: =CORREL($AF:$AF,Z:Z) -> 0.61735904 | BA12: =CORREL($AF:$AF,AA:AA) -> 0.92036127 | BB12: =CORREL($AF:$AF,AB:AB) -> 0.98579454 | BC12: =CORREL($AF:$AF,AC:AC) -> 0.9934178 | BD12: =CORREL($AF:$AF,AD:AD) -> 0.99771818 | BE12: =CORREL($AF:$AF,AE:AE) -> 0.94406295 | BF12: =CORREL($AF:$AF,AF:AF) -> 1 | BG12: =CORREL($AF:$AF,AG:AG) -> 0.91774095 | BH12: =CORREL($AF:$AF,AH:AH) -> -0.083075547 | BI12: =CORREL($AF:$AF,AI:AI) -> 0.82973893 | BJ12: =CORREL($AF:$AF,AJ:AJ) -> -0.80488593 | BK12: =CORREL($AF:$AF,AK:AK) -> 0.72856095 | BL12: =CORREL($AF:$AF,AL:AL) -> 0.9935593 | BM12: =CORREL($AF:$AF,AM:AM) -> 0.96248554 | BN12: =CORREL($AF:$AF,AN:AN) -> 0.96422181 | BO12: =CORREL($AF:$AF,AO:AO) -> 0.68286744
A13: Game:Game(IFleet) | B13: =VLOOKUP(CONCATENATE($A13,B$1),Game!$D:$G,4,0) -> 0 | C13: =VLOOKUP(CONCATENATE($A13,C$1),Game!$D:$G,4,0) -> 0 | D13: =VLOOKUP(CONCATENATE($A13,D$1),Game!$D:$G,4,0) -> 0 | E13: =VLOOKUP(CONCATENATE($A13,E$1),Game!$D:$G,4,0) -> 0 | F13: =VLOOKUP(CONCATENATE($A13,F$1),Game!$D:$G,4,0) -> 0 | G13: =VLOOKUP(CONCATENATE($A13,G$1),Game!$D:$G,4,0) -> 1.875 | H13: =VLOOKUP(CONCATENATE($A13,H$1),Game!$D:$G,4,0) -> 205.1118 | I13: =VLOOKUP(CONCATENATE($A13,I$1),Game!$D:$G,4,0) -> 0.0116 | ... U13: =VLOOKUP(CONCATENATE($A13,U$1),Game!$D:$G,4,0) -> 1 | V13: =(B13-MIN(B:B))/(MAX(B:B)-MIN(B:B)) -> 0 | W13: =(C13-MIN(C:C))/(MAX(C:C)-MIN(C:C)) -> 0 | X13: =(D13-MIN(D:D))/(MAX(D:D)-MIN(D:D)) -> 0 | Y13: =(E13-MIN(E:E))/(MAX(E:E)-MIN(E:E)) -> 0 | Z13: =(F13-MIN(F:F))/(MAX(F:F)-MIN(F:F)) -> 0 | AA13: =(G13-MIN(G:G))/(MAX(G:G)-MIN(G:G)) -> 0.019765837 | AB13: =(H13-MIN(H:H))/(MAX(H:H)-MIN(H:H)) -> 0.003267698 | AC13: =(I13-MIN(I:I))/(MAX(I:I)-MIN(I:I)) -> 0.020680325 | AD13: =(J13-MIN(J:J))/(MAX(J:J)-MIN(J:J)) -> 0.1146789 | AE13: =(K13-MIN(K:K))/(MAX(K:K)-MIN(K:K)) -> 0.17910448 | AF13: =(L13-MIN(L:L))/(MAX(L:L)-MIN(L:L)) -> 0.077520161 | AG13: =(M13-MIN(M:M))/(MAX(M:M)-MIN(M:M)) -> 0.13636364 | AH13: =(N13-MIN(N:N))/(MAX(N:N)-MIN(N:N)) -> 1 | AI13: =(O13-MIN(O:O))/(MAX(O:O)-MIN(O:O)) -> 0 | AJ13: =(P13-MIN(P:P))/(MAX(P:P)-MIN(P:P)) -> 0.55695254 | AK13: =(Q13-MIN(Q:Q))/(MAX(Q:Q)-MIN(Q:Q)) -> 0 | AL13: =(R13-MIN(R:R))/(MAX(R:R)-MIN(R:R)) -> 0 | AM13: =(S13-MIN(S:S))/(MAX(S:S)-MIN(S:S)) -> 0.33333333 | AN13: =(T13-MIN(T:T))/(MAX(T:T)-MIN(T:T)) -> 0 | AO13: =(U13-MIN(U:U))/(MAX(U:U)-MIN(U:U)) -> 0.25 | AP13: =X13+AH13+Z13+AO13 -> 1.25 | AU13: LOC | AV13: =CORREL($AG:$AG,V:V) -> 0.92099723 | AW13: =CORREL($AG:$AG,W:W) -> 0.88153871 | AX13: =CORREL($AG:$AG,X:X) -> 0.42114264 | AY13: =CORREL($AG:$AG,Y:Y) -> 0.92071233 | AZ13: =CORREL($AG:$AG,Z:Z) -> 0.61602232 | BA13: =CORREL($AG:$AG,AA:AA) -> 0.94721914 | BB13: =CORREL($AG:$AG,AB:AB) -> 0.84649702 | BC13: =CORREL($AG:$AG,AC:AC) -> 0.9159573 | BD13: =CORREL($AG:$AG,AD:AD) -> 0.93397053 | BE13: =CORREL($AG:$AG,AE:AE) -> 0.98190476 | BF13: =CORREL($AG:$AG,AF:AF) -> 0.91774095 | BG13: =CORREL($AG:$AG,AG:AG) -> 1 | BH13: =CORREL($AG:$AG,AH:AH) -> -0.20949567 | BI13: =CORREL($AG:$AG,AI:AI) -> 0.86408417 | BJ13: =CORREL($AG:$AG,AJ:AJ) -> -0.9515368 | BK13: =CORREL($AG:$AG,AK:AK) -> 0.88735745 | BL13: =CORREL($AG:$AG,AL:AL) -> 0.90402331 | BM13: =CORREL($AG:$AG,AM:AM) -> 0.91351274 | BN13: =CORREL($AG:$AG,AN:AN) -> 0.81488003 | BO13: =CORREL($AG:$AG,AO:AO) -> 0.61126698
A14: Game:getHits() | B14: =VLOOKUP(CONCATENATE($A14,B$1),Game!$D:$G,4,0) -> 0 | C14: =VLOOKUP(CONCATENATE($A14,C$1),Game!$D:$G,4,0) -> 0 | D14: =VLOOKUP(CONCATENATE($A14,D$1),Game!$D:$G,4,0) -> 0 | E14: =VLOOKUP(CONCATENATE($A14,E$1),Game!$D:$G,4,0) -> 0 | F14: =VLOOKUP(CONCATENATE($A14,F$1),Game!$D:$G,4,0) -> 0 | G14: =VLOOKUP(CONCATENATE($A14,G$1),Game!$D:$G,4,0) -> 2 | H14: =VLOOKUP(CONCATENATE($A14,H$1),Game!$D:$G,4,0) -> 23.2193 | I14: =VLOOKUP(CONCATENATE($A14,I$1),Game!$D:$G,4,0) -> 0.0027 | ... U14: =VLOOKUP(CONCATENATE($A14,U$1),Game!$D:$G,4,0) -> 0 | V14: =(B14-MIN(B:B))/(MAX(B:B)-MIN(B:B)) -> 0 | W14: =(C14-MIN(C:C))/(MAX(C:C)-MIN(C:C)) -> 0 | X14: =(D14-MIN(D:D))/(MAX(D:D)-MIN(D:D)) -> 0 | Y14: =(E14-MIN(E:E))/(MAX(E:E)-MIN(E:E)) -> 0 | Z14: =(F14-MIN(F:F))/(MAX(F:F)-MIN(F:F)) -> 0 | AA14: =(G14-MIN(G:G))/(MAX(G:G)-MIN(G:G)) -> 0.022589528 | AB14: =(H14-MIN(H:H))/(MAX(H:H)-MIN(H:H)) -> 0.00030114303 | AC14: =(I14-MIN(I:I))/(MAX(I:I)-MIN(I:I)) -> 0.0034789331 | AD14: =(J14-MIN(J:J))/(MAX(J:J)-MIN(J:J)) -> 0.0091743119 | AE14: =(K14-MIN(K:K))/(MAX(K:K)-MIN(K:K)) -> 0.029850746 | AF14: =(L14-MIN(L:L))/(MAX(L:L)-MIN(L:L)) -> 0.0050782454 | AG14: =(M14-MIN(M:M))/(MAX(M:M)-MIN(M:M)) -> 0.015151515 | AH14: =(N14-MIN(N:N))/(MAX(N:N)-MIN(N:N)) -> 1 | AI14: =(O14-MIN(O:O))/(MAX(O:O)-MIN(O:O)) -> 0 | AJ14: =(P14-MIN(P:P))/(MAX(P:P)-MIN(P:P)) -> 0.92865161 | AK14: =(Q14-MIN(Q:Q))/(MAX(Q:Q)-MIN(Q:Q)) -> 0 | AL14: =(R14-MIN(R:R))/(MAX(R:R)-MIN(R:R)) -> 0 | AM14: =(S14-MIN(S:S))/(MAX(S:S)-MIN(S:S)) -> 0 | AN14: =(T14-MIN(T:T))/(MAX(T:T)-MIN(T:T)) -> 0 | AO14: =(U14-MIN(U:U))/(MAX(U:U)-MIN(U:U)) -> 0 | AP14: =X14+AH14+Z14+AO14 -> 1 | AU14: LAA | AV14: =CORREL($AH:$AH,V:V) -> -0.038836356 | AW14: =CORREL($AH:$AH,W:W) -> 0.08358682 | AX14: =CORREL($AH:$AH,X:X) -> -0.36205403 | AY14: =CORREL($AH:$AH,Y:Y) -> -0.24614771 | AZ14: =CORREL($AH:$AH,Z:Z) -> -0.78403007 | BA14: =CORREL($AH:$AH,AA:AA) -> -0.13253455 | BB14: =CORREL($AH:$AH,AB:AB) -> -0.049112571 | BC14: =CORREL($AH:$AH,AC:AC) -> -0.078455403 | BD14: =CORREL($AH:$AH,AD:AD) -> -0.097860912 | BE14: =CORREL($AH:$AH,AE:AE) -> -0.150433 | BF14: =CORREL($AH:$AH,AF:AF) -> -0.083075547 | BG14: =CORREL($AH:$AH,AG:AG) -> -0.20949567 | BH14: =CORREL($AH:$AH,AH:AH) -> 1 | BI14: =CORREL($AH:$AH,AI:AI) -> -0.18884072 | BJ14: =CORREL($AH:$AH,AJ:AJ) -> 0.24496158 | BK14: =CORREL($AH:$AH,AK:AK) -> -0.072192789 | BL14: =CORREL($AH:$AH,AL:AL) -> -0.050457863 | BM14: =CORREL($AH:$AH,AM:AM) -> -0.089156301 | BN14: =CORREL($AH:$AH,AN:AN) -> -0.079178102 | BO14: =CORREL($AH:$AH,AO:AO) -> 0.02977514
A15: Game:getInvalidShots() | B15: =VLOOKUP(CONCATENATE($A15,B$1),Game!$D:$G,4,0) -> 0 | C15: =VLOOKUP(CONCATENATE($A15,C$1),Game!$D:$G,4,0) -> 0 | D15: =VLOOKUP(CONCATENATE($A15,D$1),Game!$D:$G,4,0) -> 0 | E15: =VLOOKUP(CONCATENATE($A15,E$1),Game!$D:$G,4,0) -> 0 | F15: =VLOOKUP(CONCATENATE($A15,F$1),Game!$D:$G,4,0) -> 0 | G15: =VLOOKUP(CONCATENATE($A15,G$1),Game!$D:$G,4,0) -> 2 | H15: =VLOOKUP(CONCATENATE($A15,H$1),Game!$D:$G,4,0) -> 23.2193 | I15: =VLOOKUP(CONCATENATE($A15,I$1),Game!$D:$G,4,0) -> 0.0027 | ... U15: =VLOOKUP(CONCATENATE($A15,U$1),Game!$D:$G,4,0) -> 0 | V15: =(B15-MIN(B:B))/(MAX(B:B)-MIN(B:B)) -> 0 | W15: =(C15-MIN(C:C))/(MAX(C:C)-MIN(C:C)) -> 0 | X15: =(D15-MIN(D:D))/(MAX(D:D)-MIN(D:D)) -> 0 | Y15: =(E15-MIN(E:E))/(MAX(E:E)-MIN(E:E)) -> 0 | Z15: =(F15-MIN(F:F))/(MAX(F:F)-MIN(F:F)) -> 0 | AA15: =(G15-MIN(G:G))/(MAX(G:G)-MIN(G:G)) -> 0.022589528 | AB15: =(H15-MIN(H:H))/(MAX(H:H)-MIN(H:H)) -> 0.00030114303 | AC15: =(I15-MIN(I:I))/(MAX(I:I)-MIN(I:I)) -> 0.0034789331 | AD15: =(J15-MIN(J:J))/(MAX(J:J)-MIN(J:J)) -> 0.0091743119 | AE15: =(K15-MIN(K:K))/(MAX(K:K)-MIN(K:K)) -> 0.029850746 | AF15: =(L15-MIN(L:L))/(MAX(L:L)-MIN(L:L)) -> 0.0050782454 | AG15: =(M15-MIN(M:M))/(MAX(M:M)-MIN(M:M)) -> 0.015151515 | AH15: =(N15-MIN(N:N))/(MAX(N:N)-MIN(N:N)) -> 1 | AI15: =(O15-MIN(O:O))/(MAX(O:O)-MIN(O:O)) -> 0 | AJ15: =(P15-MIN(P:P))/(MAX(P:P)-MIN(P:P)) -> 0.92865161 | AK15: =(Q15-MIN(Q:Q))/(MAX(Q:Q)-MIN(Q:Q)) -> 0 | AL15: =(R15-MIN(R:R))/(MAX(R:R)-MIN(R:R)) -> 0 | AM15: =(S15-MIN(S:S))/(MAX(S:S)-MIN(S:S)) -> 0 | AN15: =(T15-MIN(T:T))/(MAX(T:T)-MIN(T:T)) -> 0 | AO15: =(U15-MIN(U:U))/(MAX(U:U)-MIN(U:U)) -> 0 | AP15: =X15+AH15+Z15+AO15 -> 1 | AU15: LND | AV15: =CORREL($AI:$AI,V:V) -> 0.82982138 | AW15: =CORREL($AI:$AI,W:W) -> 0.78604072 | AX15: =CORREL($AI:$AI,X:X) -> 0.50244663 | AY15: =CORREL($AI:$AI,Y:Y) -> 0.8967561 | AZ15: =CORREL($AI:$AI,Z:Z) -> 0.64071161 | BA15: =CORREL($AI:$AI,AA:AA) -> 0.86464224 | BB15: =CORREL($AI:$AI,AB:AB) -> 0.79000024 | BC15: =CORREL($AI:$AI,AC:AC) -> 0.84337015 | BD15: =CORREL($AI:$AI,AD:AD) -> 0.83810654 | BE15: =CORREL($AI:$AI,AE:AE) -> 0.89813774 | BF15: =CORREL($AI:$AI,AF:AF) -> 0.82973893 | BG15: =CORREL($AI:$AI,AG:AG) -> 0.86408417 | BH15: =CORREL($AI:$AI,AH:AH) -> -0.18884072 | BI15: =CORREL($AI:$AI,AI:AI) -> 1 | BJ15: =CORREL($AI:$AI,AJ:AJ) -> -0.82576646 | BK15: =CORREL($AI:$AI,AK:AK) -> 0.70416148 | BL15: =CORREL($AI:$AI,AL:AL) -> 0.82524277 | BM15: =CORREL($AI:$AI,AM:AM) -> 0.81333501 | BN15: =CORREL($AI:$AI,AN:AN) -> 0.83200296 | BO15: =CORREL($AI:$AI,AO:AO) -> 0.43369087
A16: Game:getRepeatedShots() | B16: =VLOOKUP(CONCATENATE($A16,B$1),Game!$D:$G,4,0) -> 0 | C16: =VLOOKUP(CONCATENATE($A16,C$1),Game!$D:$G,4,0) -> 0 | D16: =VLOOKUP(CONCATENATE($A16,D$1),Game!$D:$G,4,0) -> 0 | E16: =VLOOKUP(CONCATENATE($A16,E$1),Game!$D:$G,4,0) -> 0 | F16: =VLOOKUP(CONCATENATE($A16,F$1),Game!$D:$G,4,0) -> 0 | G16: =VLOOKUP(CONCATENATE($A16,G$1),Game!$D:$G,4,0) -> 2 | H16: =VLOOKUP(CONCATENATE($A16,H$1),Game!$D:$G,4,0) -> 23.2193 | I16: =VLOOKUP(CONCATENATE($A16,I$1),Game!$D:$G,4,0) -> 0.0027 | ... U16: =VLOOKUP(CONCATENATE($A16,U$1),Game!$D:$G,4,0) -> 0 | V16: =(B16-MIN(B:B))/(MAX(B:B)-MIN(B:B)) -> 0 | W16: =(C16-MIN(C:C))/(MAX(C:C)-MIN(C:C)) -> 0 | X16: =(D16-MIN(D:D))/(MAX(D:D)-MIN(D:D)) -> 0 | Y16: =(E16-MIN(E:E))/(MAX(E:E)-MIN(E:E)) -> 0 | Z16: =(F16-MIN(F:F))/(MAX(F:F)-MIN(F:F)) -> 0 | AA16: =(G16-MIN(G:G))/(MAX(G:G)-MIN(G:G)) -> 0.022589528 | AB16: =(H16-MIN(H:H))/(MAX(H:H)-MIN(H:H)) -> 0.00030114303 | AC16: =(I16-MIN(I:I))/(MAX(I:I)-MIN(I:I)) -> 0.0034789331 | AD16: =(J16-MIN(J:J))/(MAX(J:J)-MIN(J:J)) -> 0.0091743119 | AE16: =(K16-MIN(K:K))/(MAX(K:K)-MIN(K:K)) -> 0.029850746 | AF16: =(L16-MIN(L:L))/(MAX(L:L)-MIN(L:L)) -> 0.0050782454 | AG16: =(M16-MIN(M:M))/(MAX(M:M)-MIN(M:M)) -> 0.015151515 | AH16: =(N16-MIN(N:N))/(MAX(N:N)-MIN(N:N)) -> 1 | AI16: =(O16-MIN(O:O))/(MAX(O:O)-MIN(O:O)) -> 0 | AJ16: =(P16-MIN(P:P))/(MAX(P:P)-MIN(P:P)) -> 0.92865161 | AK16: =(Q16-MIN(Q:Q))/(MAX(Q:Q)-MIN(Q:Q)) -> 0 | AL16: =(R16-MIN(R:R))/(MAX(R:R)-MIN(R:R)) -> 0 | AM16: =(S16-MIN(S:S))/(MAX(S:S)-MIN(S:S)) -> 0 | AN16: =(T16-MIN(T:T))/(MAX(T:T)-MIN(T:T)) -> 0 | AO16: =(U16-MIN(U:U))/(MAX(U:U)-MIN(U:U)) -> 0 | AP16: =X16+AH16+Z16+AO16 -> 1 | AU16: MMI | AV16: =CORREL($AJ:$AJ,V:V) -> -0.81395685 | AW16: =CORREL($AJ:$AJ,W:W) -> -0.84950507 | AX16: =CORREL($AJ:$AJ,X:X) -> -0.52647635 | AY16: =CORREL($AJ:$AJ,Y:Y) -> -0.88964258 | AZ16: =CORREL($AJ:$AJ,Z:Z) -> -0.56256049 | BA16: =CORREL($AJ:$AJ,AA:AA) -> -0.8970562 | BB16: =CORREL($AJ:$AJ,AB:AB) -> -0.69903081 | BC16: =CORREL($AJ:$AJ,AC:AC) -> -0.80174498 | BD16: =CORREL($AJ:$AJ,AD:AD) -> -0.83888277 | BE16: =CORREL($AJ:$AJ,AE:AE) -> -0.94174696 | BF16: =CORREL($AJ:$AJ,AF:AF) -> -0.80488593 | BG16: =CORREL($AJ:$AJ,AG:AG) -> -0.9515368 | BH16: =CORREL($AJ:$AJ,AH:AH) -> 0.24496158 | BI16: =CORREL($AJ:$AJ,AI:AI) -> -0.82576646 | BJ16: =CORREL($AJ:$AJ,AJ:AJ) -> 1 | BK16: =CORREL($AJ:$AJ,AK:AK) -> -0.88392698 | BL16: =CORREL($AJ:$AJ,AL:AL) -> -0.78599223 | BM16: =CORREL($AJ:$AJ,AM:AM) -> -0.852846 | BN16: =CORREL($AJ:$AJ,AN:AN) -> -0.66860768 | BO16: =CORREL($AJ:$AJ,AO:AO) -> -0.57810949
A17: Game:getSunkShips() | B17: =VLOOKUP(CONCATENATE($A17,B$1),Game!$D:$G,4,0) -> 0 | C17: =VLOOKUP(CONCATENATE($A17,C$1),Game!$D:$G,4,0) -> 0 | D17: =VLOOKUP(CONCATENATE($A17,D$1),Game!$D:$G,4,0) -> 0 | E17: =VLOOKUP(CONCATENATE($A17,E$1),Game!$D:$G,4,0) -> 0 | F17: =VLOOKUP(CONCATENATE($A17,F$1),Game!$D:$G,4,0) -> 0 | G17: =VLOOKUP(CONCATENATE($A17,G$1),Game!$D:$G,4,0) -> 2 | H17: =VLOOKUP(CONCATENATE($A17,H$1),Game!$D:$G,4,0) -> 23.2193 | I17: =VLOOKUP(CONCATENATE($A17,I$1),Game!$D:$G,4,0) -> 0.0027 | ... U17: =VLOOKUP(CONCATENATE($A17,U$1),Game!$D:$G,4,0) -> 0 | V17: =(B17-MIN(B:B))/(MAX(B:B)-MIN(B:B)) -> 0 | W17: =(C17-MIN(C:C))/(MAX(C:C)-MIN(C:C)) -> 0 | X17: =(D17-MIN(D:D))/(MAX(D:D)-MIN(D:D)) -> 0 | Y17: =(E17-MIN(E:E))/(MAX(E:E)-MIN(E:E)) -> 0 | Z17: =(F17-MIN(F:F))/(MAX(F:F)-MIN(F:F)) -> 0 | AA17: =(G17-MIN(G:G))/(MAX(G:G)-MIN(G:G)) -> 0.022589528 | AB17: =(H17-MIN(H:H))/(MAX(H:H)-MIN(H:H)) -> 0.00030114303 | AC17: =(I17-MIN(I:I))/(MAX(I:I)-MIN(I:I)) -> 0.0034789331 | AD17: =(J17-MIN(J:J))/(MAX(J:J)-MIN(J:J)) -> 0.0091743119 | AE17: =(K17-MIN(K:K))/(MAX(K:K)-MIN(K:K)) -> 0.029850746 | AF17: =(L17-MIN(L:L))/(MAX(L:L)-MIN(L:L)) -> 0.0050782454 | AG17: =(M17-MIN(M:M))/(MAX(M:M)-MIN(M:M)) -> 0.015151515 | AH17: =(N17-MIN(N:N))/(MAX(N:N)-MIN(N:N)) -> 1 | AI17: =(O17-MIN(O:O))/(MAX(O:O)-MIN(O:O)) -> 0 | AJ17: =(P17-MIN(P:P))/(MAX(P:P)-MIN(P:P)) -> 0.92865161 | AK17: =(Q17-MIN(Q:Q))/(MAX(Q:Q)-MIN(Q:Q)) -> 0 | AL17: =(R17-MIN(R:R))/(MAX(R:R)-MIN(R:R)) -> 0 | AM17: =(S17-MIN(S:S))/(MAX(S:S)-MIN(S:S)) -> 0 | AN17: =(T17-MIN(T:T))/(MAX(T:T)-MIN(T:T)) -> 0 | AO17: =(U17-MIN(U:U))/(MAX(U:U)-MIN(U:U)) -> 0 | AP17: =X17+AH17+Z17+AO17 -> 1 | AU17: MND | AV17: =CORREL($AK:$AK,V:V) -> 0.79183639 | AW17: =CORREL($AK:$AK,W:W) -> 0.8820059 | AX17: =CORREL($AK:$AK,X:X) -> 0.35211897 | AY17: =CORREL($AK:$AK,Y:Y) -> 0.90206372 | AZ17: =CORREL($AK:$AK,Z:Z) -> 0.38018781 | BA17: =CORREL($AK:$AK,AA:AA) -> 0.88848527 | BB17: =CORREL($AK:$AK,AB:AB) -> 0.633273 | BC17: =CORREL($AK:$AK,AC:AC) -> 0.75368714 | BD17: =CORREL($AK:$AK,AD:AD) -> 0.75621609 | BE17: =CORREL($AK:$AK,AE:AE) -> 0.87099015 | BF17: =CORREL($AK:$AK,AF:AF) -> 0.72856095 | BG17: =CORREL($AK:$AK,AG:AG) -> 0.88735745 | BH17: =CORREL($AK:$AK,AH:AH) -> -0.072192789 | BI17: =CORREL($AK:$AK,AI:AI) -> 0.70416148 | BJ17: =CORREL($AK:$AK,AJ:AJ) -> -0.88392698 | BK17: =CORREL($AK:$AK,AK:AK) -> 1 | BL17: =CORREL($AK:$AK,AL:AL) -> 0.73183781 | BM17: =CORREL($AK:$AK,AM:AM) -> 0.69414643 | BN17: =CORREL($AK:$AK,AN:AN) -> 0.55529608 | BO17: =CORREL($AK:$AK,AO:AO) -> 0.45571526
A18: Game:getAlienFleet() | B18: =VLOOKUP(CONCATENATE($A18,B$1),Game!$D:$G,4,0) -> 0 | C18: =VLOOKUP(CONCATENATE($A18,C$1),Game!$D:$G,4,0) -> 0 | D18: =VLOOKUP(CONCATENATE($A18,D$1),Game!$D:$G,4,0) -> 0 | E18: =VLOOKUP(CONCATENATE($A18,E$1),Game!$D:$G,4,0) -> 0 | F18: =VLOOKUP(CONCATENATE($A18,F$1),Game!$D:$G,4,0) -> 0 | G18: =VLOOKUP(CONCATENATE($A18,G$1),Game!$D:$G,4,0) -> 1 | H18: =VLOOKUP(CONCATENATE($A18,H$1),Game!$D:$G,4,0) -> 4.7549 | I18: =VLOOKUP(CONCATENATE($A18,I$1),Game!$D:$G,4,0) -> 0.0009 | ... U18: =VLOOKUP(CONCATENATE($A18,U$1),Game!$D:$G,4,0) -> 0 | V18: =(B18-MIN(B:B))/(MAX(B:B)-MIN(B:B)) -> 0 | W18: =(C18-MIN(C:C))/(MAX(C:C)-MIN(C:C)) -> 0 | X18: =(D18-MIN(D:D))/(MAX(D:D)-MIN(D:D)) -> 0 | Y18: =(E18-MIN(E:E))/(MAX(E:E)-MIN(E:E)) -> 0 | Z18: =(F18-MIN(F:F))/(MAX(F:F)-MIN(F:F)) -> 0 | AA18: =(G18-MIN(G:G))/(MAX(G:G)-MIN(G:G)) -> 0 | AB18: =(H18-MIN(H:H))/(MAX(H:H)-MIN(H:H)) -> 0 | AC18: =(I18-MIN(I:I))/(MAX(I:I)-MIN(I:I)) -> 0 | AD18: =(J18-MIN(J:J))/(MAX(J:J)-MIN(J:J)) -> 0 | AE18: =(K18-MIN(K:K))/(MAX(K:K)-MIN(K:K)) -> 0 | AF18: =(L18-MIN(L:L))/(MAX(L:L)-MIN(L:L)) -> 0 | AG18: =(M18-MIN(M:M))/(MAX(M:M)-MIN(M:M)) -> 0.015151515 | AH18: =(N18-MIN(N:N))/(MAX(N:N)-MIN(N:N)) -> 1 | AI18: =(O18-MIN(O:O))/(MAX(O:O)-MIN(O:O)) -> 0 | AJ18: =(P18-MIN(P:P))/(MAX(P:P)-MIN(P:P)) -> 1 | AK18: =(Q18-MIN(Q:Q))/(MAX(Q:Q)-MIN(Q:Q)) -> 0 | AL18: =(R18-MIN(R:R))/(MAX(R:R)-MIN(R:R)) -> 0 | AM18: =(S18-MIN(S:S))/(MAX(S:S)-MIN(S:S)) -> 0 | AN18: =(T18-MIN(T:T))/(MAX(T:T)-MIN(T:T)) -> 0 | AO18: =(U18-MIN(U:U))/(MAX(U:U)-MIN(U:U)) -> 0 | AP18: =X18+AH18+Z18+AO18 -> 1 | AU18: CC | AV18: =CORREL($AL:$AL,V:V) -> 0.9947552 | AW18: =CORREL($AL:$AL,W:W) -> 0.9003531 | AX18: =CORREL($AL:$AL,X:X) -> 0.35268334 | AY18: =CORREL($AL:$AL,Y:Y) -> 0.8151689 | AZ18: =CORREL($AL:$AL,Z:Z) -> 0.58729592 | BA18: =CORREL($AL:$AL,AA:AA) -> 0.92068794 | BB18: =CORREL($AL:$AL,AB:AB) -> 0.9830733 | BC18: =CORREL($AL:$AL,AC:AC) -> 0.99070163 | BD18: =CORREL($AL:$AL,AD:AD) -> 0.98991922 | BE18: =CORREL($AL:$AL,AE:AE) -> 0.93270907 | BF18: =CORREL($AL:$AL,AF:AF) -> 0.9935593 | BG18: =CORREL($AL:$AL,AG:AG) -> 0.90402331 | BH18: =CORREL($AL:$AL,AH:AH) -> -0.050457863 | BI18: =CORREL($AL:$AL,AI:AI) -> 0.82524277 | BJ18: =CORREL($AL:$AL,AJ:AJ) -> -0.78599223 | BK18: =CORREL($AL:$AL,AK:AK) -> 0.73183781 | BL18: =CORREL($AL:$AL,AL:AL) -> 1 | BM18: =CORREL($AL:$AL,AM:AM) -> 0.93608769 | BN18: =CORREL($AL:$AL,AN:AN) -> 0.95887982 | BO18: =CORREL($AL:$AL,AO:AO) -> 0.68005879
A19: Game:getAlienMoves() | B19: =VLOOKUP(CONCATENATE($A19,B$1),Game!$D:$G,4,0) -> 0 | C19: =VLOOKUP(CONCATENATE($A19,C$1),Game!$D:$G,4,0) -> 0 | D19: =VLOOKUP(CONCATENATE($A19,D$1),Game!$D:$G,4,0) -> 0 | E19: =VLOOKUP(CONCATENATE($A19,E$1),Game!$D:$G,4,0) -> 0 | F19: =VLOOKUP(CONCATENATE($A19,F$1),Game!$D:$G,4,0) -> 0 | G19: =VLOOKUP(CONCATENATE($A19,G$1),Game!$D:$G,4,0) -> 1 | H19: =VLOOKUP(CONCATENATE($A19,H$1),Game!$D:$G,4,0) -> 4.7549 | I19: =VLOOKUP(CONCATENATE($A19,I$1),Game!$D:$G,4,0) -> 0.0009 | ... U19: =VLOOKUP(CONCATENATE($A19,U$1),Game!$D:$G,4,0) -> 0 | V19: =(B19-MIN(B:B))/(MAX(B:B)-MIN(B:B)) -> 0 | W19: =(C19-MIN(C:C))/(MAX(C:C)-MIN(C:C)) -> 0 | X19: =(D19-MIN(D:D))/(MAX(D:D)-MIN(D:D)) -> 0 | Y19: =(E19-MIN(E:E))/(MAX(E:E)-MIN(E:E)) -> 0 | Z19: =(F19-MIN(F:F))/(MAX(F:F)-MIN(F:F)) -> 0 | AA19: =(G19-MIN(G:G))/(MAX(G:G)-MIN(G:G)) -> 0 | AB19: =(H19-MIN(H:H))/(MAX(H:H)-MIN(H:H)) -> 0 | AC19: =(I19-MIN(I:I))/(MAX(I:I)-MIN(I:I)) -> 0 | AD19: =(J19-MIN(J:J))/(MAX(J:J)-MIN(J:J)) -> 0 | AE19: =(K19-MIN(K:K))/(MAX(K:K)-MIN(K:K)) -> 0 | AF19: =(L19-MIN(L:L))/(MAX(L:L)-MIN(L:L)) -> 0 | AG19: =(M19-MIN(M:M))/(MAX(M:M)-MIN(M:M)) -> 0.015151515 | AH19: =(N19-MIN(N:N))/(MAX(N:N)-MIN(N:N)) -> 1 | AI19: =(O19-MIN(O:O))/(MAX(O:O)-MIN(O:O)) -> 0 | AJ19: =(P19-MIN(P:P))/(MAX(P:P)-MIN(P:P)) -> 1 | AK19: =(Q19-MIN(Q:Q))/(MAX(Q:Q)-MIN(Q:Q)) -> 0 | AL19: =(R19-MIN(R:R))/(MAX(R:R)-MIN(R:R)) -> 0 | AM19: =(S19-MIN(S:S))/(MAX(S:S)-MIN(S:S)) -> 0 | AN19: =(T19-MIN(T:T))/(MAX(T:T)-MIN(T:T)) -> 0 | AO19: =(U19-MIN(U:U))/(MAX(U:U)-MIN(U:U)) -> 0 | AP19: =X19+AH19+Z19+AO19 -> 1 | AU19: NOAV | AV19: =CORREL($AM:$AM,V:V) -> 0.92641613 | AW19: =CORREL($AM:$AM,W:W) -> 0.81936828 | AX19: =CORREL($AM:$AM,X:X) -> 0.31578823 | AY19: =CORREL($AM:$AM,Y:Y) -> 0.78477534 | AZ19: =CORREL($AM:$AM,Z:Z) -> 0.58792257 | BA19: =CORREL($AM:$AM,AA:AA) -> 0.87777901 | BB19: =CORREL($AM:$AM,AB:AB) -> 0.92512215 | BC19: =CORREL($AM:$AM,AC:AC) -> 0.94146277 | BD19: =CORREL($AM:$AM,AD:AD) -> 0.9699008 | BE19: =CORREL($AM:$AM,AE:AE) -> 0.94073433 | BF19: =CORREL($AM:$AM,AF:AF) -> 0.96248554 | BG19: =CORREL($AM:$AM,AG:AG) -> 0.91351274 | BH19: =CORREL($AM:$AM,AH:AH) -> -0.089156301 | BI19: =CORREL($AM:$AM,AI:AI) -> 0.81333501 | BJ19: =CORREL($AM:$AM,AJ:AJ) -> -0.852846 | BK19: =CORREL($AM:$AM,AK:AK) -> 0.69414643 | BL19: =CORREL($AM:$AM,AL:AL) -> 0.93608769 | BM19: =CORREL($AM:$AM,AM:AM) -> 1 | BN19: =CORREL($AM:$AM,AN:AN) -> 0.91163053 | BO19: =CORREL($AM:$AM,AO:AO) -> 0.74248745
